Workbook

Sheet 캘린더
J1: =date(year(today()), month(today()), 1) -> 46235 | M1: =IFERROR(__xludf.DUMMYFUNCTION("query(holidays!$A:$C, ""select B where A = ""&year(B2), 1)"),"Date") -> Date | N1: =IFERROR(__xludf.DUMMYFUNCTION("query('개인 일정표'!$A:$C, ""select B where A = ""&year(B2), 1)"),"#REF!") -> #REF!
B2: =date(year(J2), month(J2), 1) -> 46235 | J2: =today() -> 46254 | M2: =IFERROR(__xludf.DUMMYFUNCTION("""COMPUTED_VALUE"""),46023.0) -> 46023
M3: =IFERROR(__xludf.DUMMYFUNCTION("""COMPUTED_VALUE"""),46069.0) -> 46069
B4: Sun | C4: Mon | D4: Tue | E4: Wed | F4: Thu | G4: Fri | H4: Sat | J4: memo | M4: =IFERROR(__xludf.DUMMYFUNCTION("""COMPUTED_VALUE"""),46070.0) -> 46070
B5: =if(weekday($B$2) - 1 > 0, ,$B$2 + (1-weekday($B$2))) | C5: =if(weekday($B$2) - 2 > 0, ,$B$2 + (2-weekday($B$2))) | D5: =if(weekday($B$2) - 3 > 0, ,$B$2 + (3-weekday($B$2))) | E5: =if(weekday($B$2) - 4 > 0, ,$B$2 + (4-weekday($B$2))) | F5: =if(weekday($B$2) - 5 > 0, ,$B$2 + (5-weekday($B$2))) | G5: =if(weekday($B$2) - 6 > 0, ,$B$2 + (6-weekday($B$2))) | H5: =if(weekday($B$2) - 7 > 0, ,$B$2 + (7-weekday($B$2))) -> 46235 | M5: =IFERROR(__xludf.DUMMYFUNCTION("""COMPUTED_VALUE"""),46071.0) -> 46071
B6: =if(countif($M:$M,B5 )>0, VLOOKUP(B5, holidays!$B:$C, 2, FALSE), )&if(AND(countif($M:$M,B5 )>0,countif($N:$N,B5 )>0)," & ", )&if(countif($N:$N,B5 )>0, VLOOKUP(B5, '개인 일정표'!$B:$C, 2, FALSE), ) | C6: =if(countif($M:$M,C5 )>0, VLOOKUP(C5, holidays!$B:$C, 2, FALSE), )&if(AND(countif($M:$M,C5 )>0,countif($N:$N,C5 )>0)," & ", )&if(countif($N:$N,C5 )>0, VLOOKUP(C5, '개인 일정표'!$B:$C, 2, FALSE), ) | D6: =if(countif($M:$M,D5 )>0, VLOOKUP(D5, holidays!$B:$C, 2, FALSE), )&if(AND(countif($M:$M,D5 )>0,countif($N:$N,D5 )>0)," & ", )&if(countif($N:$N,D5 )>0, VLOOKUP(D5, '개인 일정표'!$B:$C, 2, FALSE), ) | E6: =if(countif($M:$M,E5 )>0, VLOOKUP(E5, holidays!$B:$C, 2, FALSE), )&if(AND(countif($M:$M,E5 )>0,countif($N:$N,E5 )>0)," & ", )&if(countif($N:$N,E5 )>0, VLOOKUP(E5, '개인 일정표'!$B:$C, 2, FALSE), ) | F6: =if(countif($M:$M,F5 )>0, VLOOKUP(F5, holidays!$B:$C, 2, FALSE), )&if(AND(countif($M:$M,F5 )>0,countif($N:$N,F5 )>0)," & ", )&if(countif($N:$N,F5 )>0, VLOOKUP(F5, '개인 일정표'!$B:$C, 2, FALSE), ) | G6: =if(countif($M:$M,G5 )>0, VLOOKUP(G5, holidays!$B:$C, 2, FALSE), )&if(AND(countif($M:$M,G5 )>0,countif($N:$N,G5 )>0)," & ", )&if(countif($N:$N,G5 )>0, VLOOKUP(G5, '개인 일정표'!$B:$C, 2, FALSE), ) | H6: =if(countif($M:$M,H5 )>0, VLOOKUP(H5, holidays!$B:$C, 2, FALSE), )&if(AND(countif($M:$M,H5 )>0,countif($N:$N,H5 )>0)," & ", )&if(countif($N:$N,H5 )>0, VLOOKUP(H5, '개인 일정표'!$B:$C, 2, FALSE), ) | M6: =IFERROR(__xludf.DUMMYFUNCTION("""COMPUTED_VALUE"""),46082.0) -> 46082
M7: =IFERROR(__xludf.DUMMYFUNCTION("""COMPUTED_VALUE"""),46083.0) -> 46083
M8: =IFERROR(__xludf.DUMMYFUNCTION("""COMPUTED_VALUE"""),46143.0) -> 46143
M9: =IFERROR(__xludf.DUMMYFUNCTION("""COMPUTED_VALUE"""),46147.0) -> 46147
M10: =IFERROR(__xludf.DUMMYFUNCTION("""COMPUTED_VALUE"""),46166.0) -> 46166
M11: =IFERROR(__xludf.DUMMYFUNCTION("""COMPUTED_VALUE"""),46167.0) -> 46167
M12: =IFERROR(__xludf.DUMMYFUNCTION("""COMPUTED_VALUE"""),46179.0) -> 46179
M13: =IFERROR(__xludf.DUMMYFUNCTION("""COMPUTED_VALUE"""),46220.0) -> 46220
B14: =H5+1 -> 46236 | C14: =B14+1 -> 46237 | D14: =C14+1 -> 46238 | E14: =D14+1 -> 46239 | F14: =E14+1 -> 46240 | G14: =F14+1 -> 46241 | H14: =G14+1 -> 46242 | M14: =IFERROR(__xludf.DUMMYFUNCTION("""COMPUTED_VALUE"""),46249.0) -> 46249
B15: =if(countif($M:$M,B14 )>0, VLOOKUP(B14, holidays!$B:$C, 2, FALSE), )&if(AND(countif($M:$M,B14 )>0,countif($N:$N,B14 )>0)," & ", )&if(countif($N:$N,B14 )>0, VLOOKUP(B14, '개인 일정표'!$B:$C, 2, FALSE), ) | C15: =if(countif($M:$M,C14 )>0, VLOOKUP(C14, holidays!$B:$C, 2, FALSE), ) &if(AND(countif($M:$M,C14 )>0,countif($N:$N,C14 )>0)," & ", ) &if(countif($N:$N,C14 )>0, VLOOKUP(C14, '개인 일정표'!$B:$C, 2, FALSE), ) | D15: 8월 4일 / 프로젝트 시작 | E15: =if(countif($M:$M,E14 )>0, VLOOKUP(E14, holidays!$B:$C, 2, FALSE), )&if(AND(countif($M:$M,E14 )>0,countif($N:$N,E14 )>0)," & ", )&if(countif($N:$N,E14 )>0, VLOOKUP(E14, '개인 일정표'!$B:$C, 2, FALSE), ) | F15: =if(countif($M:$M,F14 )>0, VLOOKUP(F14, holidays!$B:$C, 2, FALSE), )&if(AND(countif($M:$M,F14 )>0,countif($N:$N,F14 )>0)," & ", )&if(countif($N:$N,F14 )>0, VLOOKUP(F14, '개인 일정표'!$B:$C, 2, FALSE), ) | G15: =if(countif($M:$M,G14 )>0, VLOOKUP(G14, holidays!$B:$C, 2, FALSE), )&if(AND(countif($M:$M,G14 )>0,countif($N:$N,G14 )>0)," & ", )&if(countif($N:$N,G14 )>0, VLOOKUP(G14, '개인 일정표'!$B:$C, 2, FALSE), ) | H15: =if(countif($M:$M,H14 )>0, VLOOKUP(H14, holidays!$B:$C, 2, FALSE), )&if(AND(countif($M:$M,H14 )>0,countif($N:$N,H14 )>0)," & ", )&if(countif($N:$N,H14 )>0, VLOOKUP(H14, '개인 일정표'!$B:$C, 2, FALSE), ) | J15: 8/8일 보충교육 | M15: =IFERROR(__xludf.DUMMYFUNCTION("""COMPUTED_VALUE"""),46289.0) -> 46289
B16: =IFERROR(IF(VLOOKUP(TEXT(B$14, "yy.mm.dd"), '협업일지(이민기)'!$B$5:$C$50, 2, FALSE)="", "", "이민기 : " & VLOOKUP(TEXT(B$14, "yy.mm.dd"), '협업일지(이민기)'!$B$5:$C$50, 2, FALSE)), "") | C16: =IFERROR(IF(VLOOKUP(TEXT(C$14, "yy.mm.dd"), '협업일지(이민기)'!$B$5:$C$50, 2, FALSE)="", "", "이민기 : " & VLOOKUP(TEXT(C$14, "yy.mm.dd"), '협업일지(이민기)'!$B$5:$C$50, 2, FALSE)), "") | D16: =IFERROR(IF(VLOOKUP(TEXT(D$14, "yy.mm.dd"), '협업일지(이민기)'!$B$5:$C$50, 2, FALSE)="", "", "이민기 : " & VLOOKUP(TEXT(D$14, "yy.mm.dd"), '협업일지(이민기)'!$B$5:$C$50, 2, FALSE)), "") -> 이민기 : Project Manager | E16: =IFERROR(IF(VLOOKUP(TEXT(E$14, "yy.mm.dd"), '협업일지(이민기)'!$B$5:$C$50, 2, FALSE)="", "", "이민기 : " & VLOOKUP(TEXT(E$14, "yy.mm.dd"), '협업일지(이민기)'!$B$5:$C$50, 2, FALSE)), "") -> 이민기 : 개인 Project | F16: =IFERROR(IF(VLOOKUP(TEXT(F$14, "yy.mm.dd"), '협업일지(이민기)'!$B$5:$C$50, 2, FALSE)="", "", "이민기 : " & VLOOKUP(TEXT(F$14, "yy.mm.dd"), '협업일지(이민기)'!$B$5:$C$50, 2, FALSE)), "") -> 이민기 : 개인 Project | G16: =IFERROR(IF(VLOOKUP(TEXT(G$14, "yy.mm.dd"), '협업일지(이민기)'!$B$5:$C$50, 2, FALSE)="", "", "이민기 : " & VLOOKUP(TEXT(G$14, "yy.mm.dd"), '협업일지(이민기)'!$B$5:$C$50, 2, FALSE)), "") -> 이민기 : 개인 Project | H16: =IFERROR(IF(VLOOKUP(TEXT(H$14, "yy.mm.dd"), '협업일지(이민기)'!$B$5:$C$50, 2, FALSE)="", "", "이민기 : " & VLOOKUP(TEXT(H$14, "yy.mm.dd"), '협업일지(이민기)'!$B$5:$C$50, 2, FALSE)), "") -> 이민기 : Model Architect | M16: =IFERROR(__xludf.DUMMYFUNCTION("""COMPUTED_VALUE"""),46290.0) -> 46290
B17: =IFERROR(IF(VLOOKUP(TEXT(B$14, "yy.mm.dd"), '협업일지(고소현)'!$B$5:$C$50, 2, FALSE)="", "", "고소현 : " & VLOOKUP(TEXT(B$14, "yy.mm.dd"), '협업일지(고소현)'!$B$5:$C$50, 2, FALSE)), "") | C17: =IFERROR(IF(VLOOKUP(TEXT(C$14, "yy.mm.dd"), '협업일지(고소현)'!$B$5:$C$50, 2, FALSE)="", "", "고소현 : " & VLOOKUP(TEXT(C$14, "yy.mm.dd"), '협업일지(고소현)'!$B$5:$C$50, 2, FALSE)), "") | D17: =IFERROR(IF(VLOOKUP(TEXT(D$14, "yy.mm.dd"), '협업일지(고소현)'!$B$5:$C$50, 2, FALSE)="", "", "고소현 : " & VLOOKUP(TEXT(D$14, "yy.mm.dd"), '협업일지(고소현)'!$B$5:$C$50, 2, FALSE)), "") -> 고소현 : Project Manager | E17: =IFERROR(IF(VLOOKUP(TEXT(E$14, "yy.mm.dd"), '협업일지(고소현)'!$B$5:$C$50, 2, FALSE)="", "", "고소현 : " & VLOOKUP(TEXT(E$14, "yy.mm.dd"), '협업일지(고소현)'!$B$5:$C$50, 2, FALSE)), "") -> 고소현 : Data Engineer | F17: =IFERROR(IF(VLOOKUP(TEXT(F$14, "yy.mm.dd"), '협업일지(고소현)'!$B$5:$C$50, 2, FALSE)="", "", "고소현 : " & VLOOKUP(TEXT(F$14, "yy.mm.dd"), '협업일지(고소현)'!$B$5:$C$50, 2, FALSE)), "") -> 고소현 : Project Manager, Model Architect | G17: =IFERROR(IF(VLOOKUP(TEXT(G$14, "yy.mm.dd"), '협업일지(고소현)'!$B$5:$C$50, 2, FALSE)="", "", "고소현 : " & VLOOKUP(TEXT(G$14, "yy.mm.dd"), '협업일지(고소현)'!$B$5:$C$50, 2, FALSE)), "") -> 고소현 : Model Architect | H17: =IFERROR(IF(VLOOKUP(TEXT(H$14, "yy.mm.dd"), '협업일지(고소현)'!$B$5:$C$50, 2, FALSE)="", "", "고소현 : " & VLOOKUP(TEXT(H$14, "yy.mm.dd"), '협업일지(고소현)'!$B$5:$C$50, 2, FALSE)), "") -> 고소현 : Model Architect, Experimentation Lead | M17: =IFERROR(__xludf.DUMMYFUNCTION("""COMPUTED_VALUE"""),46291.0) -> 46291
B18: =IFERROR(IF(VLOOKUP(TEXT(B$14, "yy.mm.dd"), '협업일지(문혜원)'!$B$5:$C$50, 2, FALSE)="", "", "문혜원 : " & VLOOKUP(TEXT(B$14, "yy.mm.dd"), '협업일지(문혜원)'!$B$5:$C$50, 2, FALSE)), "") | C18: =IFERROR(IF(VLOOKUP(TEXT(C$14, "yy.mm.dd"), '협업일지(문혜원)'!$B$5:$C$50, 2, FALSE)="", "", "문혜원 : " & VLOOKUP(TEXT(C$14, "yy.mm.dd"), '협업일지(문혜원)'!$B$5:$C$50, 2, FALSE)), "") | D18: =IFERROR(IF(VLOOKUP(TEXT(D$14, "yy.mm.dd"), '협업일지(문혜원)'!$B$5:$C$50, 2, FALSE)="", "", "문혜원 : " & VLOOKUP(TEXT(D$14, "yy.mm.dd"), '협업일지(문혜원)'!$B$5:$C$50, 2, FALSE)), "") -> 문혜원 : Project Manager | E18: =IFERROR(IF(VLOOKUP(TEXT(E$14, "yy.mm.dd"), '협업일지(문혜원)'!$B$5:$C$50, 2, FALSE)="", "", "문혜원 : " & VLOOKUP(TEXT(E$14, "yy.mm.dd"), '협업일지(문혜원)'!$B$5:$C$50, 2, FALSE)), "") -> 문혜원 : 개인 Project | F18: =IFERROR(IF(VLOOKUP(TEXT(F$14, "yy.mm.dd"), '협업일지(문혜원)'!$B$5:$C$50, 2, FALSE)="", "", "문혜원 : " & VLOOKUP(TEXT(F$14, "yy.mm.dd"), '협업일지(문혜원)'!$B$5:$C$50, 2, FALSE)), "") -> 문혜원 : Data Engineer | G18: =IFERROR(IF(VLOOKUP(TEXT(G$14, "yy.mm.dd"), '협업일지(문혜원)'!$B$5:$C$50, 2, FALSE)="", "", "문혜원 : " & VLOOKUP(TEXT(G$14, "yy.mm.dd"), '협업일지(문혜원)'!$B$5:$C$50, 2, FALSE)), "") -> 문혜원 : Model Architect | H18: =IFERROR(IF(VLOOKUP(TEXT(H$14, "yy.mm.dd"), '협업일지(문혜원)'!$B$5:$C$50, 2, FALSE)="", "", "문혜원 : " & VLOOKUP(TEXT(H$14, "yy.mm.dd"), '협업일지(문혜원)'!$B$5:$C$50, 2, FALSE)), "") -> 문혜원 : Experimentation Lead | M18: =IFERROR(__xludf.DUMMYFUNCTION("""COMPUTED_VALUE"""),46298.0) -> 46298
B19: =IFERROR(IF(VLOOKUP(TEXT(B$14, "yy.mm.dd"), '협업일지(서정철)'!$B$5:$C$50, 2, FALSE)="", "", "서정철 : " & VLOOKUP(TEXT(B$14, "yy.mm.dd"), '협업일지(서정철)'!$B$5:$C$50, 2, FALSE)), "") | C19: =IFERROR(IF(VLOOKUP(TEXT(C$14, "yy.mm.dd"), '협업일지(서정철)'!$B$5:$C$50, 2, FALSE)="", "", "서정철 : " & VLOOKUP(TEXT(C$14, "yy.mm.dd"), '협업일지(서정철)'!$B$5:$C$50, 2, FALSE)), "") | D19: =IFERROR(IF(VLOOKUP(TEXT(D$14, "yy.mm.dd"), '협업일지(서정철)'!$B$5:$C$50, 2, FALSE)="", "", "서정철 : " & VLOOKUP(TEXT(D$14, "yy.mm.dd"), '협업일지(서정철)'!$B$5:$C$50, 2, FALSE)), "") -> 서정철 : 기타 | E19: =IFERROR(IF(VLOOKUP(TEXT(E$14, "yy.mm.dd"), '협업일지(서정철)'!$B$5:$C$50, 2, FALSE)="", "", "서정철 : " & VLOOKUP(TEXT(E$14, "yy.mm.dd"), '협업일지(서정철)'!$B$5:$C$50, 2, FALSE)), "") -> 서정철 : Data Engineer | F19: =IFERROR(IF(VLOOKUP(TEXT(F$14, "yy.mm.dd"), '협업일지(서정철)'!$B$5:$C$50, 2, FALSE)="", "", "서정철 : " & VLOOKUP(TEXT(F$14, "yy.mm.dd"), '협업일지(서정철)'!$B$5:$C$50, 2, FALSE)), "") -> 서정철 : Model Architect, Data Engineer | G19: =IFERROR(IF(VLOOKUP(TEXT(G$14, "yy.mm.dd"), '협업일지(서정철)'!$B$5:$C$50, 2, FALSE)="", "", "서정철 : " & VLOOKUP(TEXT(G$14, "yy.mm.dd"), '협업일지(서정철)'!$B$5:$C$50, 2, FALSE)), "") -> 서정철 : Model Architect, Data Engineer | H19: =IFERROR(IF(VLOOKUP(TEXT(H$14, "yy.mm.dd"), '협업일지(서정철)'!$B$5:$C$50, 2, FALSE)="", "", "서정철 : " & VLOOKUP(TEXT(H$14, "yy.mm.dd"), '협업일지(서정철)'!$B$5:$C$50, 2, FALSE)), "") | M19: =IFERROR(__xludf.DUMMYFUNCTION("""COMPUTED_VALUE"""),46304.0) -> 46304
B20: =IFERROR(IF(VLOOKUP(TEXT(B$14, "yy.mm.dd"), '협력일지(김경원)'!$B$5:$C$50, 2, FALSE)="", "", "김경원 : " & VLOOKUP(TEXT(B$14, "yy.mm.dd"), '협력일지(김경원)'!$B$5:$C$50, 2, FALSE)), "") | C20: =IFERROR(IF(VLOOKUP(TEXT(C$14, "yy.mm.dd"), '협력일지(김경원)'!$B$5:$C$50, 2, FALSE)="", "", "김경원 : " & VLOOKUP(TEXT(C$14, "yy.mm.dd"), '협력일지(김경원)'!$B$5:$C$50, 2, FALSE)), "") | D20: =IFERROR(IF(VLOOKUP(TEXT(D$14, "yy.mm.dd"), '협력일지(김경원)'!$B$5:$C$50, 2, FALSE)="", "", "김경원 : " & VLOOKUP(TEXT(D$14, "yy.mm.dd"), '협력일지(김경원)'!$B$5:$C$50, 2, FALSE)), "") -> 김경원 : 개인 Project | E20: =IFERROR(IF(VLOOKUP(TEXT(E$14, "yy.mm.dd"), '협력일지(김경원)'!$B$5:$C$50, 2, FALSE)="", "", "김경원 : " & VLOOKUP(TEXT(E$14, "yy.mm.dd"), '협력일지(김경원)'!$B$5:$C$50, 2, FALSE)), "") -> 김경원 : 개인 Project | F20: =IFERROR(IF(VLOOKUP(TEXT(F$14, "yy.mm.dd"), '협력일지(김경원)'!$B$5:$C$50, 2, FALSE)="", "", "김경원 : " & VLOOKUP(TEXT(F$14, "yy.mm.dd"), '협력일지(김경원)'!$B$5:$C$50, 2, FALSE)), "") -> 김경원 : 개인 Project | G20: =IFERROR(IF(VLOOKUP(TEXT(G$14, "yy.mm.dd"), '협력일지(김경원)'!$B$5:$C$50, 2, FALSE)="", "", "김경원 : " & VLOOKUP(TEXT(G$14, "yy.mm.dd"), '협력일지(김경원)'!$B$5:$C$50, 2, FALSE)), "") -> 김경원 : 개인 Project | H20: =IFERROR(IF(VLOOKUP(TEXT(H$14, "yy.mm.dd"), '협력일지(김경원)'!$B$5:$C$50, 2, FALSE)="", "", "김경원 : " & VLOOKUP(TEXT(H$14, "yy.mm.dd"), '협력일지(김경원)'!$B$5:$C$50, 2, FALSE)), "") | M20: =IFERROR(__xludf.DUMMYFUNCTION("""COMPUTED_VALUE"""),46381.0) -> 46381
B21: =IFERROR(IF(VLOOKUP(TEXT(B$14, "yy.mm.dd"), '협력일지(나상훈)'!$B$5:$C$50, 2, FALSE)="", "", "나상훈 : " & VLOOKUP(TEXT(B$14, "yy.mm.dd"), '협력일지(나상훈)'!$B$5:$C$50, 2, FALSE)), "") | C21: =IFERROR(IF(VLOOKUP(TEXT(C$14, "yy.mm.dd"), '협력일지(나상훈)'!$B$5:$C$50, 2, FALSE)="", "", "나상훈 : " & VLOOKUP(TEXT(C$14, "yy.mm.dd"), '협력일지(나상훈)'!$B$5:$C$50, 2, FALSE)), "") | D21: =IFERROR(IF(VLOOKUP(TEXT(D$14, "yy.mm.dd"), '협력일지(나상훈)'!$B$5:$C$50, 2, FALSE)="", "", "나상훈 : " & VLOOKUP(TEXT(D$14, "yy.mm.dd"), '협력일지(나상훈)'!$B$5:$C$50, 2, FALSE)), "") -> 나상훈 : 기타 | E21: =IFERROR(IF(VLOOKUP(TEXT(E$14, "yy.mm.dd"), '협력일지(나상훈)'!$B$5:$C$50, 2, FALSE)="", "", "나상훈 : " & VLOOKUP(TEXT(E$14, "yy.mm.dd"), '협력일지(나상훈)'!$B$5:$C$50, 2, FALSE)), "") -> 나상훈 : Data Engineer | F21: =IFERROR(IF(VLOOKUP(TEXT(F$14, "yy.mm.dd"), '협력일지(나상훈)'!$B$5:$C$50, 2, FALSE)="", "", "나상훈 : " & VLOOKUP(TEXT(F$14, "yy.mm.dd"), '협력일지(나상훈)'!$B$5:$C$50, 2, FALSE)), "") -> 나상훈 : Data Engineer | G21: =IFERROR(IF(VLOOKUP(TEXT(G$14, "yy.mm.dd"), '협력일지(나상훈)'!$B$5:$C$50, 2, FALSE)="", "", "나상훈 : " & VLOOKUP(TEXT(G$14, "yy.mm.dd"), '협력일지(나상훈)'!$B$5:$C$50, 2, FALSE)), "") -> 나상훈 : Model Architect | H21: =IFERROR(IF(VLOOKUP(TEXT(H$14, "yy.mm.dd"), '협력일지(나상훈)'!$B$5:$C$50, 2, FALSE)="", "", "나상훈 : " & VLOOKUP(TEXT(H$14, "yy.mm.dd"), '협력일지(나상훈)'!$B$5:$C$50, 2, FALSE)), "") -> 나상훈 : Experimentation Lead
B22: =H14+1 -> 46243 | C22: =B22+1 -> 46244 | D22: =C22+1 -> 46245 | E22: =D22+1 -> 46246 | F22: =E22+1 -> 46247 | G22: =F22+1 -> 46248 | H22: =G22+1 -> 46249
B23: =if(countif($M:$M,B22 )>0, VLOOKUP(B22, holidays!$B:$C, 2, FALSE), )&if(AND(countif($M:$M,B22 )>0,countif($N:$N,B22 )>0)," & ", )&if(countif($N:$N,B22 )>0, VLOOKUP(B22, '개인 일정표'!$B:$C, 2, FALSE), ) | C23: basic project(part 1) 마감일 | D23: =if(countif($M:$M,D22 )>0, VLOOKUP(D22, holidays!$B:$C, 2, FALSE), )&if(AND(countif($M:$M,D22 )>0,countif($N:$N,D22 )>0)," & ", )&if(countif($N:$N,D22 )>0, VLOOKUP(D22, '개인 일정표'!$B:$C, 2, FALSE), ) | E23: =if(countif($M:$M,E22 )>0, VLOOKUP(E22, holidays!$B:$C, 2, FALSE), )&if(AND(countif($M:$M,E22 )>0,countif($N:$N,E22 )>0)," & ", )&if(countif($N:$N,E22 )>0, VLOOKUP(E22, '개인 일정표'!$B:$C, 2, FALSE), ) | F23: =if(countif($M:$M,F22 )>0, VLOOKUP(F22, holidays!$B:$C, 2, FALSE), )&if(AND(countif($M:$M,F22 )>0,countif($N:$N,F22 )>0)," & ", )&if(countif($N:$N,F22 )>0, VLOOKUP(F22, '개인 일정표'!$B:$C, 2, FALSE), ) | G23: =if(countif($M:$M,G22 )>0, VLOOKUP(G22, holidays!$B:$C, 2, FALSE), )&if(AND(countif($M:$M,G22 )>0,countif($N:$N,G22 )>0)," & ", )&if(countif($N:$N,G22 )>0, VLOOKUP(G22, '개인 일정표'!$B:$C, 2, FALSE), ) | H23: =if(countif($M:$M,H22 )>0, VLOOKUP(H22, holidays!$B:$C, 2, FALSE), )&if(AND(countif($M:$M,H22 )>0,countif($N:$N,H22 )>0)," & ", )&if(countif($N:$N,H22 )>0, VLOOKUP(H22, '개인 일정표'!$B:$C, 2, FALSE), ) -> 광복절
B24: =IFERROR(IF(VLOOKUP(TEXT(B$22, "yy.mm.dd"), '협업일지(이민기)'!$B$5:$C$50, 2, FALSE)="", "", "이민기 : " & VLOOKUP(TEXT(B$22, "yy.mm.dd"), '협업일지(이민기)'!$B$5:$C$50, 2, FALSE)), "") -> 이민기 : Model Architect | C24: =IFERROR(IF(VLOOKUP(TEXT(C$22, "yy.mm.dd"), '협업일지(이민기)'!$B$5:$C$50, 2, FALSE)="", "", "이민기 : " & VLOOKUP(TEXT(C$22, "yy.mm.dd"), '협업일지(이민기)'!$B$5:$C$50, 2, FALSE)), "") -> 이민기 : Model Architect, Data Engineer | D24: =IFERROR(IF(VLOOKUP(TEXT(D$22, "yy.mm.dd"), '협업일지(이민기)'!$B$5:$C$50, 2, FALSE)="", "", "이민기 : " & VLOOKUP(TEXT(D$22, "yy.mm.dd"), '협업일지(이민기)'!$B$5:$C$50, 2, FALSE)), "") -> 이민기 : Model Architect | E24: =IFERROR(IF(VLOOKUP(TEXT(E$22, "yy.mm.dd"), '협업일지(이민기)'!$B$5:$C$50, 2, FALSE)="", "", "이민기 : " & VLOOKUP(TEXT(E$22, "yy.mm.dd"), '협업일지(이민기)'!$B$5:$C$50, 2, FALSE)), "") -> 이민기 : 휴가 | F24: =IFERROR(IF(VLOOKUP(TEXT(F$22, "yy.mm.dd"), '협업일지(이민기)'!$B$5:$C$50, 2, FALSE)="", "", "이민기 : " & VLOOKUP(TEXT(F$22, "yy.mm.dd"), '협업일지(이민기)'!$B$5:$C$50, 2, FALSE)), "") -> 이민기 : Model Architect | G24: =IFERROR(IF(VLOOKUP(TEXT(G$22, "yy.mm.dd"), '협업일지(이민기)'!$B$5:$C$50, 2, FALSE)="", "", "이민기 : " & VLOOKUP(TEXT(G$22, "yy.mm.dd"), '협업일지(이민기)'!$B$5:$C$50, 2, FALSE)), "") -> 이민기 : Model Architect | H24: =IFERROR(IF(VLOOKUP(TEXT(H$22, "yy.mm.dd"), '협업일지(이민기)'!$B$5:$C$50, 2, FALSE)="", "", "이민기 : " & VLOOKUP(TEXT(H$22, "yy.mm.dd"), '협업일지(이민기)'!$B$5:$C$50, 2, FALSE)), "")
B25: =IFERROR(IF(VLOOKUP(TEXT(B$22, "yy.mm.dd"), '협업일지(고소현)'!$B$5:$C$50, 2, FALSE)="", "", "고소현 : " & VLOOKUP(TEXT(B$22, "yy.mm.dd"), '협업일지(고소현)'!$B$5:$C$50, 2, FALSE)), "") | C25: =IFERROR(IF(VLOOKUP(TEXT(C$22, "yy.mm.dd"), '협업일지(고소현)'!$B$5:$C$50, 2, FALSE)="", "", "고소현 : " & VLOOKUP(TEXT(C$22, "yy.mm.dd"), '협업일지(고소현)'!$B$5:$C$50, 2, FALSE)), "") -> 고소현 : Model Architect | D25: =IFERROR(IF(VLOOKUP(TEXT(D$22, "yy.mm.dd"), '협업일지(고소현)'!$B$5:$C$50, 2, FALSE)="", "", "고소현 : " & VLOOKUP(TEXT(D$22, "yy.mm.dd"), '협업일지(고소현)'!$B$5:$C$50, 2, FALSE)), "") -> 고소현 : Model Architect | E25: =IFERROR(IF(VLOOKUP(TEXT(E$22, "yy.mm.dd"), '협업일지(고소현)'!$B$5:$C$50, 2, FALSE)="", "", "고소현 : " & VLOOKUP(TEXT(E$22, "yy.mm.dd"), '협업일지(고소현)'!$B$5:$C$50, 2, FALSE)), "") -> 고소현 : 기타 | F25: =IFERROR(IF(VLOOKUP(TEXT(F$22, "yy.mm.dd"), '협업일지(고소현)'!$B$5:$C$50, 2, FALSE)="", "", "고소현 : " & VLOOKUP(TEXT(F$22, "yy.mm.dd"), '협업일지(고소현)'!$B$5:$C$50, 2, FALSE)), "") | G25: =IFERROR(IF(VLOOKUP(TEXT(G$22, "yy.mm.dd"), '협업일지(고소현)'!$B$5:$C$50, 2, FALSE)="", "", "고소현 : " & VLOOKUP(TEXT(G$22, "yy.mm.dd"), '협업일지(고소현)'!$B$5:$C$50, 2, FALSE)), "") | H25: =IFERROR(IF(VLOOKUP(TEXT(H$22, "yy.mm.dd"), '협업일지(고소현)'!$B$5:$C$50, 2, FALSE)="", "", "고소현 : " & VLOOKUP(TEXT(H$22, "yy.mm.dd"), '협업일지(고소현)'!$B$5:$C$50, 2, FALSE)), "")
B26: =IFERROR(IF(VLOOKUP(TEXT(B$22, "yy.mm.dd"), '협업일지(문혜원)'!$B$5:$C$50, 2, FALSE)="", "", "문혜원 : " & VLOOKUP(TEXT(B$22, "yy.mm.dd"), '협업일지(문혜원)'!$B$5:$C$50, 2, FALSE)), "") | C26: =IFERROR(IF(VLOOKUP(TEXT(C$22, "yy.mm.dd"), '협업일지(문혜원)'!$B$5:$C$50, 2, FALSE)="", "", "문혜원 : " & VLOOKUP(TEXT(C$22, "yy.mm.dd"), '협업일지(문혜원)'!$B$5:$C$50, 2, FALSE)), "") -> 문혜원 : Model Architect | D26: =IFERROR(IF(VLOOKUP(TEXT(D$22, "yy.mm.dd"), '협업일지(문혜원)'!$B$5:$C$50, 2, FALSE)="", "", "문혜원 : " & VLOOKUP(TEXT(D$22, "yy.mm.dd"), '협업일지(문혜원)'!$B$5:$C$50, 2, FALSE)), "") -> 문혜원 : Experimentation Lead | E26: =IFERROR(IF(VLOOKUP(TEXT(E$22, "yy.mm.dd"), '협업일지(문혜원)'!$B$5:$C$50, 2, FALSE)="", "", "문혜원 : " & VLOOKUP(TEXT(E$22, "yy.mm.dd"), '협업일지(문혜원)'!$B$5:$C$50, 2, FALSE)), "") -> 문혜원 : Experimentation Lead | F26: =IFERROR(IF(VLOOKUP(TEXT(F$22, "yy.mm.dd"), '협업일지(문혜원)'!$B$5:$C$50, 2, FALSE)="", "", "문혜원 : " & VLOOKUP(TEXT(F$22, "yy.mm.dd"), '협업일지(문혜원)'!$B$5:$C$50, 2, FALSE)), "") -> 문혜원 : 휴가 | G26: =IFERROR(IF(VLOOKUP(TEXT(G$22, "yy.mm.dd"), '협업일지(문혜원)'!$B$5:$C$50, 2, FALSE)="", "", "문혜원 : " & VLOOKUP(TEXT(G$22, "yy.mm.dd"), '협업일지(문혜원)'!$B$5:$C$50, 2, FALSE)), "") -> 문혜원 : 휴가 | H26: =IFERROR(IF(VLOOKUP(TEXT(H$22, "yy.mm.dd"), '협업일지(문혜원)'!$B$5:$C$50, 2, FALSE)="", "", "문혜원 : " & VLOOKUP(TEXT(H$22, "yy.mm.dd"), '협업일지(문혜원)'!$B$5:$C$50, 2, FALSE)), "")
B27: =IFERROR(IF(VLOOKUP(TEXT(B$22, "yy.mm.dd"), '협업일지(서정철)'!$B$5:$C$50, 2, FALSE)="", "", "서정철 : " & VLOOKUP(TEXT(B$22, "yy.mm.dd"), '협업일지(서정철)'!$B$5:$C$50, 2, FALSE)), "") | C27: =IFERROR(IF(VLOOKUP(TEXT(C$22, "yy.mm.dd"), '협업일지(서정철)'!$B$5:$C$50, 2, FALSE)="", "", "서정철 : " & VLOOKUP(TEXT(C$22, "yy.mm.dd"), '협업일지(서정철)'!$B$5:$C$50, 2, FALSE)), "") -> 서정철 : Model Architect | D27: =IFERROR(IF(VLOOKUP(TEXT(D$22, "yy.mm.dd"), '협업일지(서정철)'!$B$5:$C$50, 2, FALSE)="", "", "서정철 : " & VLOOKUP(TEXT(D$22, "yy.mm.dd"), '협업일지(서정철)'!$B$5:$C$50, 2, FALSE)), "") -> 서정철 : Model Architect | E27: =IFERROR(IF(VLOOKUP(TEXT(E$22, "yy.mm.dd"), '협업일지(서정철)'!$B$5:$C$50, 2, FALSE)="", "", "서정철 : " & VLOOKUP(TEXT(E$22, "yy.mm.dd"), '협업일지(서정철)'!$B$5:$C$50, 2, FALSE)), "") -> 서정철 : Model Architect | F27: =IFERROR(IF(VLOOKUP(TEXT(F$22, "yy.mm.dd"), '협업일지(서정철)'!$B$5:$C$50, 2, FALSE)="", "", "서정철 : " & VLOOKUP(TEXT(F$22, "yy.mm.dd"), '협업일지(서정철)'!$B$5:$C$50, 2, FALSE)), "") -> 서정철 : Data Engineer | G27: =IFERROR(IF(VLOOKUP(TEXT(G$22, "yy.mm.dd"), '협업일지(서정철)'!$B$5:$C$50, 2, FALSE)="", "", "서정철 : " & VLOOKUP(TEXT(G$22, "yy.mm.dd"), '협업일지(서정철)'!$B$5:$C$50, 2, FALSE)), "") -> 서정철 : 휴가 | H27: =IFERROR(IF(VLOOKUP(TEXT(H$22, "yy.mm.dd"), '협업일지(서정철)'!$B$5:$C$50, 2, FALSE)="", "", "서정철 : " & VLOOKUP(TEXT(H$22, "yy.mm.dd"), '협업일지(서정철)'!$B$5:$C$50, 2, FALSE)), "")
B28: =IFERROR(IF(VLOOKUP(TEXT(B$22, "yy.mm.dd"), '협력일지(김경원)'!$B$5:$C$50, 2, FALSE)="", "", "김경원 : " & VLOOKUP(TEXT(B$22, "yy.mm.dd"), '협력일지(김경원)'!$B$5:$C$50, 2, FALSE)), "") | C28: =IFERROR(IF(VLOOKUP(TEXT(C$22, "yy.mm.dd"), '협력일지(김경원)'!$B$5:$C$50, 2, FALSE)="", "", "김경원 : " & VLOOKUP(TEXT(C$22, "yy.mm.dd"), '협력일지(김경원)'!$B$5:$C$50, 2, FALSE)), "") -> 김경원 : 개인 Project | D28: =IFERROR(IF(VLOOKUP(TEXT(D$22, "yy.mm.dd"), '협력일지(김경원)'!$B$5:$C$50, 2, FALSE)="", "", "김경원 : " & VLOOKUP(TEXT(D$22, "yy.mm.dd"), '협력일지(김경원)'!$B$5:$C$50, 2, FALSE)), "") -> 김경원 : 휴가 | E28: =IFERROR(IF(VLOOKUP(TEXT(E$22, "yy.mm.dd"), '협력일지(김경원)'!$B$5:$C$50, 2, FALSE)="", "", "김경원 : " & VLOOKUP(TEXT(E$22, "yy.mm.dd"), '협력일지(김경원)'!$B$5:$C$50, 2, FALSE)), "") -> 김경원 : 개인 Project | F28: =IFERROR(IF(VLOOKUP(TEXT(F$22, "yy.mm.dd"), '협력일지(김경원)'!$B$5:$C$50, 2, FALSE)="", "", "김경원 : " & VLOOKUP(TEXT(F$22, "yy.mm.dd"), '협력일지(김경원)'!$B$5:$C$50, 2, FALSE)), "") -> 김경원 : 개인 Project | G28: =IFERROR(IF(VLOOKUP(TEXT(G$22, "yy.mm.dd"), '협력일지(김경원)'!$B$5:$C$50, 2, FALSE)="", "", "김경원 : " & VLOOKUP(TEXT(G$22, "yy.mm.dd"), '협력일지(김경원)'!$B$5:$C$50, 2, FALSE)), "") -> 김경원 : 개인 Project | H28: =IFERROR(IF(VLOOKUP(TEXT(H$22, "yy.mm.dd"), '협력일지(김경원)'!$B$5:$C$50, 2, FALSE)="", "", "김경원 : " & VLOOKUP(TEXT(H$22, "yy.mm.dd"), '협력일지(김경원)'!$B$5:$C$50, 2, FALSE)), "")
B29: =IFERROR(IF(VLOOKUP(TEXT(B$22, "yy.mm.dd"), '협력일지(나상훈)'!$B$5:$C$50, 2, FALSE)="", "", "나상훈 : " & VLOOKUP(TEXT(B$22, "yy.mm.dd"), '협력일지(나상훈)'!$B$5:$C$50, 2, FALSE)), "") | C29: =IFERROR(IF(VLOOKUP(TEXT(C$22, "yy.mm.dd"), '협력일지(나상훈)'!$B$5:$C$50, 2, FALSE)="", "", "나상훈 : " & VLOOKUP(TEXT(C$22, "yy.mm.dd"), '협력일지(나상훈)'!$B$5:$C$50, 2, FALSE)), "") -> 나상훈 : 휴가 | D29: =IFERROR(IF(VLOOKUP(TEXT(D$22, "yy.mm.dd"), '협력일지(나상훈)'!$B$5:$C$50, 2, FALSE)="", "", "나상훈 : " & VLOOKUP(TEXT(D$22, "yy.mm.dd"), '협력일지(나상훈)'!$B$5:$C$50, 2, FALSE)), "") -> 나상훈 : Experimentation Lead | E29: =IFERROR(IF(VLOOKUP(TEXT(E$22, "yy.mm.dd"), '협력일지(나상훈)'!$B$5:$C$50, 2, FALSE)="", "", "나상훈 : " & VLOOKUP(TEXT(E$22, "yy.mm.dd"), '협력일지(나상훈)'!$B$5:$C$50, 2, FALSE)), "") -> 나상훈 : Data Engineer | F29: =IFERROR(IF(VLOOKUP(TEXT(F$22, "yy.mm.dd"), '협력일지(나상훈)'!$B$5:$C$50, 2, FALSE)="", "", "나상훈 : " & VLOOKUP(TEXT(F$22, "yy.mm.dd"), '협력일지(나상훈)'!$B$5:$C$50, 2, FALSE)), "") -> 나상훈 : Data Engineer | G29: =IFERROR(IF(VLOOKUP(TEXT(G$22, "yy.mm.dd"), '협력일지(나상훈)'!$B$5:$C$50, 2, FALSE)="", "", "나상훈 : " & VLOOKUP(TEXT(G$22, "yy.mm.dd"), '협력일지(나상훈)'!$B$5:$C$50, 2, FALSE)), "") -> 나상훈 : Model Architect | H29: =IFERROR(IF(VLOOKUP(TEXT(H$22, "yy.mm.dd"), '협력일지(나상훈)'!$B$5:$C$50, 2, FALSE)="", "", "나상훈 : " & VLOOKUP(TEXT(H$22, "yy.mm.dd"), '협력일지(나상훈)'!$B$5:$C$50, 2, FALSE)), "")
B30: =H22+1 -> 46250 | C30: =B30+1 -> 46251 | D30: =C30+1 -> 46252 | E30: =D30+1 -> 46253 | F30: =E30+1 -> 46254 | G30: =F30+1 -> 46255 | H30: =G30+1 -> 46256
B31: =if(countif($M:$M,B30 )>0, VLOOKUP(B30, holidays!$B:$C, 2, FALSE), )&if(AND(countif($M:$M,B30 )>0,countif($N:$N,B30 )>0)," & ", )&if(countif($N:$N,B30 )>0, VLOOKUP(B30, '개인 일정표'!$B:$C, 2, FALSE), ) | C31: =if(countif($M:$M,C30 )>0, VLOOKUP(C30, holidays!$B:$C, 2, FALSE), )&if(AND(countif($M:$M,C30 )>0,countif($N:$N,C30 )>0)," & ", )&if(countif($N:$N,C30 )>0, VLOOKUP(C30, '개인 일정표'!$B:$C, 2, FALSE), ) | D31: =if(countif($M:$M,D30 )>0, VLOOKUP(D30, holidays!$B:$C, 2, FALSE), )&if(AND(countif($M:$M,D30 )>0,countif($N:$N,D30 )>0)," & ", )&if(countif($N:$N,D30 )>0, VLOOKUP(D30, '개인 일정표'!$B:$C, 2, FALSE), ) | E31: =if(countif($M:$M,E30 )>0, VLOOKUP(E30, holidays!$B:$C, 2, FALSE), )&if(AND(countif($M:$M,E30 )>0,countif($N:$N,E30 )>0)," & ", )&if(countif($N:$N,E30 )>0, VLOOKUP(E30, '개인 일정표'!$B:$C, 2, FALSE), ) | F31: =if(countif($M:$M,F30 )>0, VLOOKUP(F30, holidays!$B:$C, 2, FALSE), )&if(AND(countif($M:$M,F30 )>0,countif($N:$N,F30 )>0)," & ", )&if(countif($N:$N,F30 )>0, VLOOKUP(F30, '개인 일정표'!$B:$C, 2, FALSE), ) | G31: 프로젝트 마감 | H31: =if(countif($M:$M,H30 )>0, VLOOKUP(H30, holidays!$B:$C, 2, FALSE), )&if(AND(countif($M:$M,H30 )>0,countif($N:$N,H30 )>0)," & ", )&if(countif($N:$N,H30 )>0, VLOOKUP(H30, '개인 일정표'!$B:$C, 2, FALSE), )
B32: =IFERROR(IF(VLOOKUP(TEXT(B$30, "yy.mm.dd"), '협업일지(이민기)'!$B$5:$C$50, 2, FALSE)="", "", "이민기 : " & VLOOKUP(TEXT(B$30, "yy.mm.dd"), '협업일지(이민기)'!$B$5:$C$50, 2, FALSE)), "") | C32: =IFERROR(IF(VLOOKUP(TEXT(C$30, "yy.mm.dd"), '협업일지(이민기)'!$B$5:$C$50, 2, FALSE)="", "", "이민기 : " & VLOOKUP(TEXT(C$30, "yy.mm.dd"), '협업일지(이민기)'!$B$5:$C$50, 2, FALSE)), "") | D32: =IFERROR(IF(VLOOKUP(TEXT(D$30, "yy.mm.dd"), '협업일지(이민기)'!$B$5:$C$50, 2, FALSE)="", "", "이민기 : " & VLOOKUP(TEXT(D$30, "yy.mm.dd"), '협업일지(이민기)'!$B$5:$C$50, 2, FALSE)), "") -> 이민기 : Project Manager | E32: =IFERROR(IF(VLOOKUP(TEXT(E$30, "yy.mm.dd"), '협업일지(이민기)'!$B$5:$C$50, 2, FALSE)="", "", "이민기 : " & VLOOKUP(TEXT(E$30, "yy.mm.dd"), '협업일지(이민기)'!$B$5:$C$50, 2, FALSE)), "") -> 이민기 : Project Manager | F32: =IFERROR(IF(VLOOKUP(TEXT(F$30, "yy.mm.dd"), '협업일지(이민기)'!$B$5:$C$50, 2, FALSE)="", "", "이민기 : " & VLOOKUP(TEXT(F$30, "yy.mm.dd"), '협업일지(이민기)'!$B$5:$C$50, 2, FALSE)), "") | G32: =IFERROR(IF(VLOOKUP(TEXT(G$30, "yy.mm.dd"), '협업일지(이민기)'!$B$5:$C$50, 2, FALSE)="", "", "이민기 : " & VLOOKUP(TEXT(G$30, "yy.mm.dd"), '협업일지(이민기)'!$B$5:$C$50, 2, FALSE)), "") | H32: =IFERROR(IF(VLOOKUP(TEXT(H$30, "yy.mm.dd"), '협업일지(이민기)'!$B$5:$C$50, 2, FALSE)="", "", "이민기 : " & VLOOKUP(TEXT(H$30, "yy.mm.dd"), '협업일지(이민기)'!$B$5:$C$50, 2, FALSE)), "")
B33: =IFERROR(IF(VLOOKUP(TEXT(B$30, "yy.mm.dd"), '협업일지(고소현)'!$B$5:$C$50, 2, FALSE)="", "", "고소현 : " & VLOOKUP(TEXT(B$30, "yy.mm.dd"), '협업일지(고소현)'!$B$5:$C$50, 2, FALSE)), "") | C33: =IFERROR(IF(VLOOKUP(TEXT(C$30, "yy.mm.dd"), '협업일지(고소현)'!$B$5:$C$50, 2, FALSE)="", "", "고소현 : " & VLOOKUP(TEXT(C$30, "yy.mm.dd"), '협업일지(고소현)'!$B$5:$C$50, 2, FALSE)), "") | D33: =IFERROR(IF(VLOOKUP(TEXT(D$30, "yy.mm.dd"), '협업일지(고소현)'!$B$5:$C$50, 2, FALSE)="", "", "고소현 : " & VLOOKUP(TEXT(D$30, "yy.mm.dd"), '협업일지(고소현)'!$B$5:$C$50, 2, FALSE)), "") | E33: =IFERROR(IF(VLOOKUP(TEXT(E$30, "yy.mm.dd"), '협업일지(고소현)'!$B$5:$C$50, 2, FALSE)="", "", "고소현 : " & VLOOKUP(TEXT(E$30, "yy.mm.dd"), '협업일지(고소현)'!$B$5:$C$50, 2, FALSE)), "") | F33: =IFERROR(IF(VLOOKUP(TEXT(F$30, "yy.mm.dd"), '협업일지(고소현)'!$B$5:$C$50, 2, FALSE)="", "", "고소현 : " & VLOOKUP(TEXT(F$30, "yy.mm.dd"), '협업일지(고소현)'!$B$5:$C$50, 2, FALSE)), "") | G33: =IFERROR(IF(VLOOKUP(TEXT(G$30, "yy.mm.dd"), '협업일지(고소현)'!$B$5:$C$50, 2, FALSE)="", "", "고소현 : " & VLOOKUP(TEXT(G$30, "yy.mm.dd"), '협업일지(고소현)'!$B$5:$C$50, 2, FALSE)), "") | H33: =IFERROR(IF(VLOOKUP(TEXT(H$30, "yy.mm.dd"), '협업일지(고소현)'!$B$5:$C$50, 2, FALSE)="", "", "고소현 : " & VLOOKUP(TEXT(H$30, "yy.mm.dd"), '협업일지(고소현)'!$B$5:$C$50, 2, FALSE)), "")
B34: =IFERROR(IF(VLOOKUP(TEXT(B$30, "yy.mm.dd"), '협업일지(문혜원)'!$B$5:$C$50, 2, FALSE)="", "", "문혜원 : " & VLOOKUP(TEXT(B$30, "yy.mm.dd"), '협업일지(문혜원)'!$B$5:$C$50, 2, FALSE)), "") | C34: =IFERROR(IF(VLOOKUP(TEXT(C$30, "yy.mm.dd"), '협업일지(문혜원)'!$B$5:$C$50, 2, FALSE)="", "", "문혜원 : " & VLOOKUP(TEXT(C$30, "yy.mm.dd"), '협업일지(문혜원)'!$B$5:$C$50, 2, FALSE)), "") | D34: =IFERROR(IF(VLOOKUP(TEXT(D$30, "yy.mm.dd"), '협업일지(문혜원)'!$B$5:$C$50, 2, FALSE)="", "", "문혜원 : " & VLOOKUP(TEXT(D$30, "yy.mm.dd"), '협업일지(문혜원)'!$B$5:$C$50, 2, FALSE)), "") -> 문혜원 : Sub (지원) | E34: =IFERROR(IF(VLOOKUP(TEXT(E$30, "yy.mm.dd"), '협업일지(문혜원)'!$B$5:$C$50, 2, FALSE)="", "", "문혜원 : " & VLOOKUP(TEXT(E$30, "yy.mm.dd"), '협업일지(문혜원)'!$B$5:$C$50, 2, FALSE)), "") -> 문혜원 : Sub (지원) | F34: =IFERROR(IF(VLOOKUP(TEXT(F$30, "yy.mm.dd"), '협업일지(문혜원)'!$B$5:$C$50, 2, FALSE)="", "", "문혜원 : " & VLOOKUP(TEXT(F$30, "yy.mm.dd"), '협업일지(문혜원)'!$B$5:$C$50, 2, FALSE)), "") -> 문혜원 : 휴가 | G34: =IFERROR(IF(VLOOKUP(TEXT(G$30, "yy.mm.dd"), '협업일지(문혜원)'!$B$5:$C$50, 2, FALSE)="", "", "문혜원 : " & VLOOKUP(TEXT(G$30, "yy.mm.dd"), '협업일지(문혜원)'!$B$5:$C$50, 2, FALSE)), "") | H34: =IFERROR(IF(VLOOKUP(TEXT(H$30, "yy.mm.dd"), '협업일지(문혜원)'!$B$5:$C$50, 2, FALSE)="", "", "문혜원 : " & VLOOKUP(TEXT(H$30, "yy.mm.dd"), '협업일지(문혜원)'!$B$5:$C$50, 2, FALSE)), "")
B35: =IFERROR(IF(VLOOKUP(TEXT(B$30, "yy.mm.dd"), '협업일지(서정철)'!$B$5:$C$50, 2, FALSE)="", "", "서정철 : " & VLOOKUP(TEXT(B$30, "yy.mm.dd"), '협업일지(서정철)'!$B$5:$C$50, 2, FALSE)), "") | C35: =IFERROR(IF(VLOOKUP(TEXT(C$30, "yy.mm.dd"), '협업일지(서정철)'!$B$5:$C$50, 2, FALSE)="", "", "서정철 : " & VLOOKUP(TEXT(C$30, "yy.mm.dd"), '협업일지(서정철)'!$B$5:$C$50, 2, FALSE)), "") | D35: =IFERROR(IF(VLOOKUP(TEXT(D$30, "yy.mm.dd"), '협업일지(서정철)'!$B$5:$C$50, 2, FALSE)="", "", "서정철 : " & VLOOKUP(TEXT(D$30, "yy.mm.dd"), '협업일지(서정철)'!$B$5:$C$50, 2, FALSE)), "") -> 서정철 : Sub (지원) | E35: =IFERROR(IF(VLOOKUP(TEXT(E$30, "yy.mm.dd"), '협업일지(서정철)'!$B$5:$C$50, 2, FALSE)="", "", "서정철 : " & VLOOKUP(TEXT(E$30, "yy.mm.dd"), '협업일지(서정철)'!$B$5:$C$50, 2, FALSE)), "") -> 서정철 : Sub (지원) | F35: =IFERROR(IF(VLOOKUP(TEXT(F$30, "yy.mm.dd"), '협업일지(서정철)'!$B$5:$C$50, 2, FALSE)="", "", "서정철 : " & VLOOKUP(TEXT(F$30, "yy.mm.dd"), '협업일지(서정철)'!$B$5:$C$50, 2, FALSE)), "") | G35: =IFERROR(IF(VLOOKUP(TEXT(G$30, "yy.mm.dd"), '협업일지(서정철)'!$B$5:$C$50, 2, FALSE)="", "", "서정철 : " & VLOOKUP(TEXT(G$30, "yy.mm.dd"), '협업일지(서정철)'!$B$5:$C$50, 2, FALSE)), "") | H35: =IFERROR(IF(VLOOKUP(TEXT(H$30, "yy.mm.dd"), '협업일지(서정철)'!$B$5:$C$50, 2, FALSE)="", "", "서정철 : " & VLOOKUP(TEXT(H$30, "yy.mm.dd"), '협업일지(서정철)'!$B$5:$C$50, 2, FALSE)), "")
B36: =IFERROR(IF(VLOOKUP(TEXT(B$30, "yy.mm.dd"), '협력일지(김경원)'!$B$5:$C$50, 2, FALSE)="", "", "김경원 : " & VLOOKUP(TEXT(B$30, "yy.mm.dd"), '협력일지(김경원)'!$B$5:$C$50, 2, FALSE)), "") | C36: =IFERROR(IF(VLOOKUP(TEXT(C$30, "yy.mm.dd"), '협력일지(김경원)'!$B$5:$C$50, 2, FALSE)="", "", "김경원 : " & VLOOKUP(TEXT(C$30, "yy.mm.dd"), '협력일지(김경원)'!$B$5:$C$50, 2, FALSE)), "") -> 김경원 : 개인 Project | D36: =IFERROR(IF(VLOOKUP(TEXT(D$30, "yy.mm.dd"), '협력일지(김경원)'!$B$5:$C$50, 2, FALSE)="", "", "김경원 : " & VLOOKUP(TEXT(D$30, "yy.mm.dd"), '협력일지(김경원)'!$B$5:$C$50, 2, FALSE)), "") -> 김경원 : 개인 Project | E36: =IFERROR(IF(VLOOKUP(TEXT(E$30, "yy.mm.dd"), '협력일지(김경원)'!$B$5:$C$50, 2, FALSE)="", "", "김경원 : " & VLOOKUP(TEXT(E$30, "yy.mm.dd"), '협력일지(김경원)'!$B$5:$C$50, 2, FALSE)), "") -> 김경원 : 개인 Project | F36: =IFERROR(IF(VLOOKUP(TEXT(F$30, "yy.mm.dd"), '협력일지(김경원)'!$B$5:$C$50, 2, FALSE)="", "", "김경원 : " & VLOOKUP(TEXT(F$30, "yy.mm.dd"), '협력일지(김경원)'!$B$5:$C$50, 2, FALSE)), "") | G36: =IFERROR(IF(VLOOKUP(TEXT(G$30, "yy.mm.dd"), '협력일지(김경원)'!$B$5:$C$50, 2, FALSE)="", "", "김경원 : " & VLOOKUP(TEXT(G$30, "yy.mm.dd"), '협력일지(김경원)'!$B$5:$C$50, 2, FALSE)), "") | H36: =IFERROR(IF(VLOOKUP(TEXT(H$30, "yy.mm.dd"), '협력일지(김경원)'!$B$5:$C$50, 2, FALSE)="", "", "김경원 : " & VLOOKUP(TEXT(H$30, "yy.mm.dd"), '협력일지(김경원)'!$B$5:$C$50, 2, FALSE)), "")
B37: =IFERROR(IF(VLOOKUP(TEXT(B$30, "yy.mm.dd"), '협력일지(나상훈)'!$B$5:$C$50, 2, FALSE)="", "", "나상훈 : " & VLOOKUP(TEXT(B$30, "yy.mm.dd"), '협력일지(나상훈)'!$B$5:$C$50, 2, FALSE)), "") | C37: =IFERROR(IF(VLOOKUP(TEXT(C$30, "yy.mm.dd"), '협력일지(나상훈)'!$B$5:$C$50, 2, FALSE)="", "", "나상훈 : " & VLOOKUP(TEXT(C$30, "yy.mm.dd"), '협력일지(나상훈)'!$B$5:$C$50, 2, FALSE)), "") | D37: =IFERROR(IF(VLOOKUP(TEXT(D$30, "yy.mm.dd"), '협력일지(나상훈)'!$B$5:$C$50, 2, FALSE)="", "", "나상훈 : " & VLOOKUP(TEXT(D$30, "yy.mm.dd"), '협력일지(나상훈)'!$B$5:$C$50, 2, FALSE)), "") -> 나상훈 : Experimentation Lead | E37: =IFERROR(IF(VLOOKUP(TEXT(E$30, "yy.mm.dd"), '협력일지(나상훈)'!$B$5:$C$50, 2, FALSE)="", "", "나상훈 : " & VLOOKUP(TEXT(E$30, "yy.mm.dd"), '협력일지(나상훈)'!$B$5:$C$50, 2, FALSE)), "") -> 나상훈 : Project Manager | F37: =IFERROR(IF(VLOOKUP(TEXT(F$30, "yy.mm.dd"), '협력일지(나상훈)'!$B$5:$C$50, 2, FALSE)="", "", "나상훈 : " & VLOOKUP(TEXT(F$30, "yy.mm.dd"), '협력일지(나상훈)'!$B$5:$C$50, 2, FALSE)), "") | G37: =IFERROR(IF(VLOOKUP(TEXT(G$30, "yy.mm.dd"), '협력일지(나상훈)'!$B$5:$C$50, 2, FALSE)="", "", "나상훈 : " & VLOOKUP(TEXT(G$30, "yy.mm.dd"), '협력일지(나상훈)'!$B$5:$C$50, 2, FALSE)), "") | H37: =IFERROR(IF(VLOOKUP(TEXT(H$30, "yy.mm.dd"), '협력일지(나상훈)'!$B$5:$C$50, 2, FALSE)="", "", "나상훈 : " & VLOOKUP(TEXT(H$30, "yy.mm.dd"), '협력일지(나상훈)'!$B$5:$C$50, 2, FALSE)), "")
B38: =if(day($H30) + 1 > day(EOMONTH($B$2,0)), , $H30 +1) -> 46257 | C38: =if(day($H30) +2 > day(EOMONTH($B$2,0)), , $H30 + 2) -> 46258 | D38: =if(day($H30) +3> day(EOMONTH($B$2,0)), , $H30 + 3) -> 46259 | E38: =if(day($H30) + 4 > day(EOMONTH($B$2,0)),, $H30 + 4) -> 46260 | F38: =if(day($H30) + 5 > day(EOMONTH($B$2,0)), , $H30 + 5) -> 46261 | G38: =if(day($H30) + 6 > day(EOMONTH($B$2,0)), , $H30 + 6) -> 46262 | H38: =if(day($H30) + 7 > day(EOMONTH($B$2,0)), , $H30 + 7) -> 46263
B39: =if(countif($M:$M,B38 )>0, VLOOKUP(B38, holidays!$B:$C, 2, FALSE), )&if(AND(countif($M:$M,B38 )>0,countif($N:$N,B38 )>0)," & ", )&if(countif($N:$N,B38 )>0, VLOOKUP(B38, '개인 일정표'!$B:$C, 2, FALSE), ) | C39: =if(countif($M:$M,C38 )>0, VLOOKUP(C38, holidays!$B:$C, 2, FALSE), )&if(AND(countif($M:$M,C38 )>0,countif($N:$N,C38 )>0)," & ", )&if(countif($N:$N,C38 )>0, VLOOKUP(C38, '개인 일정표'!$B:$C, 2, FALSE), ) | D39: =if(countif($M:$M,D38 )>0, VLOOKUP(D38, holidays!$B:$C, 2, FALSE), )&if(AND(countif($M:$M,D38 )>0,countif($N:$N,D38 )>0)," & ", )&if(countif($N:$N,D38 )>0, VLOOKUP(D38, '개인 일정표'!$B:$C, 2, FALSE), ) | E39: =if(countif($M:$M,E38 )>0, VLOOKUP(E38, holidays!$B:$C, 2, FALSE), )&if(AND(countif($M:$M,E38 )>0,countif($N:$N,E38 )>0)," & ", )&if(countif($N:$N,E38 )>0, VLOOKUP(E38, '개인 일정표'!$B:$C, 2, FALSE), ) | F39: =if(countif($M:$M,F38 )>0, VLOOKUP(F38, holidays!$B:$C, 2, FALSE), )&if(AND(countif($M:$M,F38 )>0,countif($N:$N,F38 )>0)," & ", )&if(countif($N:$N,F38 )>0, VLOOKUP(F38, '개인 일정표'!$B:$C, 2, FALSE), ) | G39: =if(countif($M:$M,G38 )>0, VLOOKUP(G38, holidays!$B:$C, 2, FALSE), )&if(AND(countif($M:$M,G38 )>0,countif($N:$N,G38 )>0)," & ", )&if(countif($N:$N,G38 )>0, VLOOKUP(G38, '개인 일정표'!$B:$C, 2, FALSE), ) | H39: =if(countif($M:$M,H38 )>0, VLOOKUP(H38, holidays!$B:$C, 2, FALSE), )&if(AND(countif($M:$M,H38 )>0,countif($N:$N,H38 )>0)," & ", )&if(countif($N:$N,H38 )>0, VLOOKUP(H38, '개인 일정표'!$B:$C, 2, FALSE), )
B44: =if(day($H30) + 8 > day(EOMONTH($B$2,0)), , $H30 + 8) -> 46264 | C44: =if(day($H30) + 9 > day(EOMONTH($B$2,0)), , $H30 + 9) -> 46265
...

Sheet 협업일지(이민기)
B1: Project : Fill so Good 개인 협업 일지 (이민기)
B4: 날짜 | C4: 작업 유형 | D4: 구체적인 작업 내용 or 협업내용 | G4: 진행율 | H4: 분석/실험 중 얻은 인사이트나 발견한 문제점 | J4: 목표 or 할일
B5: 26.08.04 | C5: Project Manager | D5: - 전체적인 프로젝트 구상 및 업무 세분화를 위한 각각의 업무 분담 부여 - 기본적인 basic 모델 구현 이후 기능을 추가하는 방안으로 수립 - EDA 및 데이터 전처리 작업 시작 | G5: 25~50% | H5: - AIHUB 데이터셋은 원본과 다르게 annotation id / image id / categori id 가 전부 1로 동일 이에 따른 데이터셋 분류 지표를 정해야함 - 한개의 이미지 파일에 최소 3개 이상의 json 파일과 연계가 되어있는 구조 yolo 모델 투입 전 데이터 처리가 필요하다고 판단 | J5: - EDA 및 데이터 전처리 과정
B6: 26.08.05 | C6: 개인 Project | D6: - 멘토링 이후 회의를 통해 개개인의 End - to - End 방식으로 진행하기로 결정 이에 따라 기본 kaggle에서 요구하는 성능지표와 이미지 탐지의 기본적인 기능을 가진 basic 모델 구현 - 현재 EDA 및 전처리 과정으로 데이터 셋 세팅 이후 4가지 후보 모델로 모델링 파트 구성 | G6: 0~25% | H6: - 이미지 파일명과 json 파일명의 관계 파악 이미지 파일은 알약의 고유값과 이미지 환경으로 설정 되어 있음 | J6: - 이미지와 json파일을 페어링 하고 yolo 모델은 1:1로 페어링이 되어야하기 때문에 데이터셋 통합 및 재구성
B7: 26.08.06 | C7: 개인 Project | D7: - 모델 학습을 위한 데이터 전처리 및 EDA 과정을 조금 더 심도 있게 다뤘음 - 본격적인 모델 학습 전 데이터셋 구성 및 데이터 로더, 전처리 파이프 라인 설계 후 전이학습 진행 예정 - 샘플을 통한 bbox를 확인 해 본 결과 문제는 없지만 다른 팀원의 의견 확인 결과 bbox 박스 좌표가 이상하게 저장이 되어 있거나 일부 누락된 케이스가 있다고 함 이를 전제로 전처리 과정을 추가 | G7: 50~75% | H7: - class_id를 drug_code를 기준으로 재 작성 결과 약 115종의 알약데이터가 여러번 사용되고 있는 점 발견 - 추후 프로젝트에 기능 추가시 원하는 데이터 셋을 얻기 위해서는더 많은 종류의 알약 데이터가 필요할 것으로 여겨지는 문제점 발견 - 우선적으로 모델 학습을 위한 전처리 transform을 사용함으로 고정된 환경에서 촬영 된 사진을 기반으로 다양한 상황을 만들어 모델 학습성능을 최대치로 끌어올리고자 전처리 라인을 설계함 | J7: - 데이터 셋 구성 이후 데이터 로더를 구성 - 모델 전이학습을 위한 헤드 교체 이후 학습을 위한 세팅 선정(ex. 옵티마이저, lr, schedular 등)
B8: 26.08.07 | C8: 개인 Project | D8: - # 원본 데이터 파일 전처리 과정 1. 원본 데이터 셋에서 매치되는 이미지 파일과 json 파일 페어링 2. 페어링 된 이미지에서 같은 이름을 사용하는 json 파일 데이터셋을 분리 이후 여러개의 json파일을 class_id / bndbox 하나로 1:1 매핑 i. durg_master.csv : 원본 json의 drug_code 알약 고유번호(classes.txt)로 구성된 필요데이터 db ii. image_meta_db.csv : _기준으로 촬영 된 환경 값 EDA 분석을 위한 db iii. classes.txt : 각 이미지에 매칭된 json 파일의 drug_code를 기준으로 중복없이 재 구성한 class_id 3. yolov8s 교육 이후 데이터 셋 활용하기 위한 txt -> json 파일 변환 매핑 # 후보 모델 라인업 1. YOLOv8 + ConvNeXt-Tiny 모델 2. YOLOv8 + Swin-T 3. YOLOv8 + EfficientNet-B 4. YOLOv8 | G8: 50~75% | H8: - 다양한 데이터 셋을 활용하기 위함으로 원본 데이터 셋인 AIhub 데이서 셋을 활용하려 했지만 알약 갯수가 많지 않다는 점을 발견 - 이에 따라 기존 part1 부분 기존 basic 모델 수립에서는 kaggle 데이터 셋을 활용해서 작성 or 원본 데이터셋을 이용 등 자율적 선택사항으로 모델작성 본인은 원본 데이터 셋을 수정 및 전처리 과정을 거쳐 head는 YOLO로 백본은 여러 전이학습 모델을 사용한 결과 값 도출을 목표 - bndbox 영역이 원본 데이터 셋에는 상당히 부실한 구성이 있다는 점 회의를 통해서 문제점 발견 및 class 별 데이터 셋이 균등하게 이뤄지지 않았기에 특정 알약만 데이터가 주를 이루는 데이터 불균형 현상 관측 (문혜원) 따라서 추후 방향성을 정할 때 데이터 불균형 문제를 해소할 모델링 구축이 필요하다고 생각됨 | J8: - YOLOv8s 학습 완료 하지만 해당 학습 데이터 셋과 목표로 하는 모델 학습 데이터 셋의 구성이 다름 - 따라서 기존 txt에 1:1로 매핑된 데이터를 다시 json파일로 변환하되 1:1 매핑방식이 아닌 고유 class_id와 image_id를 부여하여 통합 json파일로 진행 할 예정
B9: 26.08.08 | C9: Model Architect | D9: 1. Yolov8s 버전의 기본 학습 데이터를 기반으로 분석한 뒤 이후 백본을 후보 모델 라인업으로 교체한 현재 데이터셋에 맞는 가장 우수한 모델을 선정하여 해당 모델로 학습 이후 하이퍼 파라미터를 변경하거나 loss를 수정하여 최종 제출과 관련된 pht(가중치)를 얻는 것을 목표로 Model Architect 파트를 진행 2. 우선 Head에 성능이 우수한 Yolo를 베이스로 진행하기 앞서 yolov8s 모델의 50epoch 기준 데이터를 기준 데이터셋으로 다양한 Head 후보 모델을 학습 및 결과 비교 - YOLOv8s - YOLOv9 comport - YOLOv11s - RT - DETR 3. 평가 결과 : 모델 성능은 기준인 mAP50-95 지표는 약 15에폭을 평균으로 대부분 0.98에 수렴 따라서 Head 선정 기준은 학습과 관련되어 얼마나 시간과 자원소모률을 기준으로 yolov8s / yolov11s이 후보군으로 선정 4. 백본 교체 : Head는 yolov11s로 선정하고 이후 백본을 ConvNeXT, swin, EfficientNet-B 모델로 교체 코딩 시작 | G9: 25~50% | H9: - Head 모델 평가는 순조롭게 진행 학습 시간이 상당히 소요된다는 단점을 제외하고는 mAP 평가지표 기준 학습률도 순조롭게 오르고 있다는 점 확인 - 이후 백본 교체와 관련되어 여러 문제점 발생.... 우선적으로 ConvNext 모델 교체과정에서 MMyolo를 이용해서 백본을 교체하여 학습결과 도출 후 최적모델 선정 파트로 진행하고자 하였으나 현재 라이브러리 오류로 mmyolo 를 사용할 수 없는 문제가 발생 - 따라서 차선책으로 하드코딩을 통한 라이브러리 및 기존 데이터셋 class 수정 및 loss 로직 수정으로 결과물 도출을 시도 - 하지만 전반적인 구조에 대한 이해가 낮아 하드코딩으로는 구현이 상당히 어려운 문제가 발생... 이후 해당 문제를 해결하기 위한 다양한 시도를 하였지만 아직까진 해결이 안되는 상황 | J9: - 초기에 정한 모델 후보군으로 백본을 교체하여 성능 비교 후 데이터셋에 맞는 최적 모델 선정
B10: 26.08.09 | C10: Model Architect
B11: 26.08.10 | C11: Model Architect, Data Engineer | D11: - 기존 8월 10일까지 연장된 기간임에도 불구하고 앞선 문제를 해결하지 못해 기간 내 완성을 하지 못해 팀원간 Head 성능만 관련되어 의견을 주고 받을 수 있었음 - 8월 10일 회의 기준 초기 목표로 잡은 기능 구현을 위해 다양한 데이터를 확보하기 위한 원본 AIhub 데이터셋을 활용하여 코딩을 한 뒤 각자 여러 모델을 사용하여 장단점을 분서한 뒤 최종 모델 후보군을 선정하기 위한 과정이 있었음 하지만 데이터셋에 따라 모델의 성능 격차가 크게 발생하는 문제도 있고 원본 데이터셋을 이용하면 kaggle에 제출할 땐 활용을 못하는 치명적인 문제가 발생 따라서 목표를 1차적으로 개인이 만든 Best 모델을 kaggle에 제출하여 점수를 확인하여 보완할 부분을 보완하고 점수를 높게 받은 모델을 분석하여 최종 프로젝트의 Model Architect를 구성하는 것으로 의견 수렴 - 회의 내용 결과 데이터셋은 1차적으로 kaggle 데이터셋 기준으로만 통일하여 작성하되 베이스 모델은 Yolo기반으로 각자 본인이 커스텀한 모델을 사용하거나 Yolov11s 모델을 사용하는 방향으로 통일(다른 모델을 사용하여 작성한 경우도 포함) - 앞선 내용을 기반으로 기존 데이터셋과 전처리 방향을 전면 수정 이후 전처리 된 데이터셋으로 백본 교체 작업 진행중에 앞선 문제와 똑같은 문제점 발생... | G11: 25~50% | H11: - 기존 하드코딩 방식 MMyolo방식 Ultralytics 방식 모든 방식을 동원하여 코딩을 진행해봤지만 터미널 오류 및 라이브러리 오류 등으로 더이상 진행이 불가 - 따라서 기존 백본 모델 후보군을 구현할 수 있는 방향으로 재탐색 및 백본 교체와 같은 성능을 내는 코딩방식에 대한 탐구 진행 - 문제점 해결 방식 탐색 중 Ultralytics의 파이토치 모델 모듈이 있다는 방법 발견 이에 따라 yaml 파일로 백본을 교체후 모델 성능 테스트 코딩으로 진행 | J11: - Ultralytics YAML + TorchVision + Index를 이용해서 Backbone을 교체 - YOLO11 기본 Backbone vs ConvNeXt-Tiny vs Swin-Tiny 를 동일한 데이터/학습 조건에서 비교
B12: 26.08.11 | C12: Model Architect | D12: - 주강사님의 피드백 이후 전체적인 프로젝트 방향성을 케글 데이터셋을 활용하여 여러 방식의 모델을 구성한 뒤 팀원 간 소통(협업)하여 가장 우수한 평가지표를 가진 최종 모델을 선정하는 방향으로 협의 - 기존 Kaggle 데이터셋만 이용하기엔 데이터불균형 및 희귀클래스 존재 등의 이유로 초기 mAP50-95 지표가 굉장히 낮은 지점에서 시작 이를 극복하려면 상당한 epoch 이후 어느정도 학습된 가중치를 기반으로 진행해야하는 문제가 있음 - 위 내용의 뒷받침을 위해 우선 구성하던 Yolov11s 모델의 전이학습으로 학습한 데이터를 표준으로 삼고 이후 다양한 backbone 교체를 통한 최적 백본을 탐색하는 과정 중 학습지표를 확인하니 위와 같은 문제점이 있기에 기존 Aihub 데이터를 가공하여 사용가능한 train 데이터셋으로 기존 kaggle 데이터와 합치는 방향으로 목표 수정 - 로직은 Yolo용 매핑 데이터셋(Kaggle / Aihub)에서 각자 classes.txt(케글은 category_id / Aihub는 drug_n)기준으로 작성된 클래스 지표를 서로 매핑하여 데이터가 부족한 특정 클래스에 대한 데이터를 가져와 재구성하는 것으로 구성 | G12: 0~25% | H12: - 초기 구상한 로직을 통하여 사용 가능한 데이터셋을 추출한 결과 약 400~500개의 데이터셋만 존재 - 이유를 확인해보니 케글 데이터셋에 존재하는 56종의 알약만으로 구성된 데이터셋은 원본 데이터셋에 약 300~400장 정도 내외로 존재 나머지는 원본 116종의 알약 데이터와 혼합되어 있는 데이터 셋이 약 7천 500장 정도 - 해당 EDA와 데이터셋 구성으로 유추 : 'Aihub-v2 경구약제조합' 이 파일이 케글의 GT로 판단 따라서 대회의 의도는 주어진 데이터셋만을 활용해서 여러 기법 및 로스 교체, 백본, 로직, 데이터 증강 등을 활용해서 가장 좋은 평가지표를 받을 수 있게 탐색하고 가장 우수한 모델을 제출하고자 하는 것이 목표
B13: 26.08.12 | C13: 휴가 | G13: -----
B14: 26.08.13 | C14: Model Architect | D14: - 모델 로직 후보 1. 합성 데이터 중심 단일 YOLO (Data-Centric Baseline) 가장 기본이 되는 모델로, '데이터의 양과 조합을 강제로 늘리면 성능이 오를 것인가?'를 검증하는 실험 탐지/분류: YOLOv11s 단일 모델 (탐지와 56종 분류를 한 번에 수행) 데이터/불균형 극복: 230장의 이미지에서 개별 알약을 잘라내어(Crop), 동일한 배경 위에 무작위로 재배치(회전, 조합 변경) 이때 부족한 희귀 클래스 알약을 더 많이 복사하여 클래스 불균형을 물리적으로 해결 Unknown 방어 로직 (Margin Thresholding): 단순히 1등 확률이 낮다고 버리는 것이 아니라, '1위 클래스 확률과 2위 클래스 확률의 격차(Margin)' 모델이 "A인지 B인지 헷갈린다(격차가 좁다)"면 확신이 없는 것이므로 Unknown으로 판정 - 모델 로직 후보 2. Two-Stage YOLO + ResNet50 앞선 단일 YOLO 모델의 분류 성능 한계를 극복하기 위한 방법으로 도입한 모델 탐지/분류: 1단계 YOLOv11s는 알약의 위치 탐지에 집중하고, 2단계 ResNet50은 탐지된 알약을 Crop하여 56종 중 어떤 약인지 정밀하게 분류 데이터/불균형 극복: 230장의 원본 데이터에서 알약을 고화질로 Crop한 뒤 GrabCut 기반 합성 및 증강을 적용하여 희귀 클래스의 데이터를 보강하고, 클래스별 학습 데이터의 균형을 맞춤 미세 분류 성능 강화: YOLO에서 Crop한 알약 이미지를 ResNet50에 입력하여 알약 표면의 각인, 색상, 형태, 텍스처 등 세부 특징을 집중적으로 학습 → 탐지와 분류를 분리하여 단일 YOLO의 Fine-grained Classification 한계를 보완 학습 방식: ResNet50의 사전학습 가중치를 활용하고, 초기에는 분류 헤드만 학습한 뒤 일부 Backbone을 낮은 학습률로 Fine-tuning하여 소량 데이터에서의 과적합을 방지 Unknown 방어 로직: ResNet50의 최종 예측 확률이 UNKNOWN_THRESHOLD(0.20) 미만이면 학습되지 않은 알약(OOD)으로 판단하여 category_id = 1(Unknown)으로 처리 | G14: ----- | H14: - 경량 모델의 한계점 : 객체 탐지 분야에서는 해당 위치에 무엇이 있는가에 대한 성능은 높은 편 다만 세부 객체를 분류하는 기능은 크게 떨어지기에 해당 위치에 무엇이 있는가? 에 대한 문제해결 능력은 높지만 반대로 그 약은 무엇인지 구분하는 능력이 크게 떨어지는 로직임을 확인 kaggle : 약 30점 내외
B15: 26.08.14 | C15: Model Architect | D15: 단계 내용 모델 후보 1. 단일 YOLO (1-Stage) YOLOv11s 하나로 알약의 Detection과 56종 Classification을 동시에 수행하는 Baseline 모델. 230장의 원본 이미지에서 개별 알약을 Crop한 후 회전, 크기 변경, 재배치, 조합 변경 등을 적용하여 합성 데이터를 생성하고, 부족한 클래스의 알약을 추가하여 데이터 불균형을 보완. Localization 성능은 양호했지만, 서로 유사한 알약을 구분하기 위해 필요한 각인, 색상, 형태, 표면 패턴 등의 Fine-grained 특징을 충분히 학습하기 어려워 Classification 성능에 한계가 확인됨. 1-Stage → Two-Stage 전환 단일 YOLO에서는 알약의 위치 탐지와 세부 약품 분류를 하나의 모델에서 동시에 수행해야 하므로, 유사한 알약 간 Fine-grained Classification에 한계가 발생. 특히 알약의 최종 분류에는 전체 이미지에서의 위치 정보보다 Crop된 객체의 각인, 문자, 색상, 형태, Texture 등 세부적인 시각 정보가 중요하다고 판단. 따라서 Detection과 Classification을 분리하여, YOLO는 알약을 정확하게 찾는 역할에 집중하고 별도의 Classification 모델을 통해 탐지된 알약을 정밀하게 분류하는 Two-Stage 구조로 전환. 모델 후보 2. Two-Stage YOLO + ResNet50 [전체 구조] 전체 이미지 → YOLOv11s Detection → Bounding Box Crop → ResNet50 Classification → 최종 Class [Stage 1. Detection - YOLOv11s] YOLOv11s는 전체 이미지에서 알약의 위치와 Bounding Box를 탐지하는 역할을 수행. 여러 알약이 동시에 존재하거나 객체 크기가 작은 이미지에서도 가능한 한 모든 알약을 놓치지 않고 탐지하는 것을 주요 목표로 설정. [Stage 2. Classification - ResNet50] YOLOv11s가 탐지한 Bounding Box를 기준으로 개별 알약을 Crop하여 ResNet50에 입력. ResNet50은 Crop된 알약 이미지에서 색상, 형태, 각인, 문자, 표면 패턴, Texture 등의 세부 특징을 집중적으로 학습하여 약품 종류를 분류. YOLO가 전체 이미지의 위치 정보를 처리하는 반면, ResNet50은 개별 알약의 세밀한 시각적 특징을 분석하도록 역할을 분리. [데이터 구성] 초기에는 약 230장의 원본 데이터를 기반으로 구축했으며, 이후 Kaggle + AI Hub 데이터를 통합하여 118종 전체를 포함하는 Unified Dataset으로 확장. 클래스별 데이터 수를 균형화하고 부족한 클래스는 알약 객체를 직접 추출하여 Synthetic Augmentation을 적용. [Classification 입력 전처리] YOLO Bounding Box를 기반으로 알약 영역을 Crop한 후 불필요한 배경이나 다른 알약이 포함된 Crop을 Filtering. 최종적으로 정제된 개별 알약 이미지를 ResNet50의 입력으로 사용하여 Classification 성능을 높이는 구조. [ResNet50 학습 방식] ImageNet 사전학습 가중치를 활용하여 적은 데이터에서도 안정적으로 학습할 수 있도록 구성. 초기에는 Classification Head를 중심으로 학습한 뒤 일부 Backbone Layer를 단계적으로 해제하여 Fine-tuning. 384×384 고해상도 입력을 사용하여 작은 각인과 표면 패턴 등 알약의 세부 정보를 최대한 보존. [최종 Inference] ResNet50의 Classification 결과에 Original, Brightness, Contrast 변형을 활용한 3-Way TTA를 적용하고 각 예측 확률을 평균하여 최종 Class를 결정. 최대 예측 확률이 충분히 높지 않은 경우 Unknown으로 처리하여 학습되지 않은 객체가 118종 중 하나로 강제 분류되는 문제를 방어. [Two-Stage의 핵심 효과] YOLOv11s는 Detection에 집중하고 ResNet50은 Fine-grained Classification에 집중하도록 역할을 분리. 이를 통해 단일 YOLO 방식에서 발생했던 유사 알약 분류 한계를 보완하고, 데이터 전처리·Filtering·Fine-tuning·TTA·OOD Defense를 Classification 단계에 독립적으로 적용할 수 있도록 Pipeline을 확장. | G15: ----- | H15: Two-Stage V1 약 230장의 Kaggle 데이터를 기반으로 YOLO → Crop → ResNet50의 초기 Pipeline 구축. 데이터 부족과 118종 Coverage 부족으로 Classification 성능이 낮았으며 F2 ≈ 0.60 기록. Two-Stage V2 [데이터 통합·정제] Kaggle + AI Hub 데이터를 통합하여 118종 Unified Dataset 구축. Image-JSON, 약품 코드, BBox 등을 검증하고 오류 데이터를 제거했으며 Group Split으로 Data Leakage를 방지. [불균형·데이터 부족 개선] 클래스별 데이터를 300장 수준으로 균형화하고, 부족한 클래스는 GrabCut 기반 알약 분리 및 Copy-Paste Synthetic Augmentation으로 보강. [Crop Filtering] Crop 영역에 다른 알약이 포함되는 Noise를 제거하여 ResNet50의 입력 품질을 개선. → F2 ≈ 0.92까지 향상. Two-Stage V3 [Detection Coverage 개선] 기존 YOLO가 일부 Class를 충분히 학습하지 못해 Detection Missing이 발생한 문제를 해결하기 위해 Kaggle + AI Hub 통합 데이터를 YOLO 학습에도 적용하여 118종 전체 Coverage 확보. 흰색 알약의 각인·표면 패턴 손상을 고려하여 증강 방식도 개선. [Unknown 대응] 학습되지 않은 객체가 118종 중 하나로 강제 분류되는 문제를 방지하기 위해 Confidence 기반 Unknown/OOD 방어 전략 도입. Two-Stage V4 [Mapping·Noise 개선] YOLO와 Unified Class Index 간 Mapping을 통일하고 Pattern Filtering을 적용하여 Label 오류와 Crop Noise를 개선. [ResNet50 학습 안정화] Pretrained ResNet50의 Head를 먼저 학습한 후 Layer4를 단계적으로 Fine-tuning하고 일부 Layer를 Freeze하여 과적합과 학습 불안정을 완화. [최종 Classification] 384×384 Crop을 사용하여 각인·색상·형태·Texture 정보를 보존하고 CosineAnnealingLR, Label Smoothing 등을 적용. 최종 Inference [3-Way TTA] Original + Brightness ×1.3 + Contrast ×1.3의 3개 입력에 대한 Softmax Probability를 평균하여 추론 안정성을 향상. [Unknown Defense] ResNet50 최대 확률이 0.20 미만이면 Unknown(Category 1)으로 처리하여 낮은 확신의 예측을 방어. 최종 Architecture 전체 이미지 → YOLOv11s Detection → BBox Crop → Filtering → ResNet50 118종 Classification → 3-Way TTA → Probability Average → Unknown Threshold → 최종 Class. 최종 결과 V1 F2 ≈ 0.60 → V2 F2 ≈ 0.92 → V4 Validation F2 ≈ 0.91. 내부 Validation에서는 높은 성능을 확보했지만 실제 Kaggle Score는 0.60으로 하락하여 Test Distribution Shift와 Unknown/OOD 문제의 중요성을 확인. 핵심 인사이트 단일 YOLO의 Fine-grained Classification 한계를 확인하고 YOLO + ResNet50 Two-Stage로 전환. 이후 데이터 통합, Coverage 확대, Class Balancing, Synthetic Augmentation, Crop Filtering, Mapping 개선, Fine-tuning 안정화, TTA 및 OOD 방어를 단계적으로 적용하여 전체 Pipeline을 개선.
B16: 26.08.15 | G16: -----
B17: 26.08.16 | G17: -----
B18: 26.08.17 | G18: -----
B19: 26.08.18 | C19: Project Manager | D19: - 팀원별 업무 배치 Github - 이민기, 최종 보고서 : 나상훈, 발표자료 : 문혜원, 서정철, 모델 튜닝 : 김경원 현 시점을 기준으로 개개인의 모델 테스트는 여러 조건 속에 진행하기 어렵다고 판단 따라서 최종 모델을 만든 팀원(김경원)을 제외하고 남은 인원은 발표와 최종보고서, github와 같은 작업을 사전에 진행하여 완성본을 기점으로 내용 공유 후 최종 마무리 단계에 진입하기로 결정 | G19: -----
B20: 26.08.19 | C20: Project Manager | D20: - Github 내용 Read me 수정 및 코드 구동에 필요한 csv / pt 파일 업로드 - 발표 자료 제작 지원 | G20: -----
B21: 26.08.20 | G21: -----
B22: 26.08.21 | G22: -----
B23: 26.08.22 | G23: -----

Sheet 협업일지(문혜원)
B1: Project : Fill so Good 개인 협업 일지 (문혜원)
B4: 날짜 | C4: 작업 유형 | D4: 구체적인 작업 내용 or 협업내용 | G4: 진행율 | H4: 분석/실험 중 얻은 인사이트나 발견한 문제점 | J4: 목표 or 할일
B5: 26.08.04 | C5: Project Manager | D5: 헬스케어 이미지 인식 프로젝트의 목표와 데이터 구조를 확인하고, 팀원들과 EDA 항목 및 모델 개발 방향을 논의하였다. 이미지 분류와 객체 탐지 방식의 차이를 검토하고 프로젝트 목표에 적합한 접근 방법을 정리하였다. | G5: 25~50% | H5: 전체 데이터 용량이 크고 Annotation 형식이 복잡하여 모델 학습 전에 데이터 구조와 클래스 분포를 먼저 파악할 필요가 있음을 확인하였다. 또한 Classification과 Object Detection은 목적과 평가지표가 다르므로 구분하여 실험해야 한다고 판단하였다. | J5: 클래스 분포와 Annotation 오류 여부를 확인하고, 객체 탐지 모델에 사용할 데이터 구조 및 전처리 방향을 구체화한다.
B6: 26.08.05 | C6: 개인 Project | D6: 오전에는 팀원들과 EDA 결과와 객체 탐지 모델 개발 방향을 공유하였다. 오후에는 FashionMNIST 데이터를 활용하여 다중 클래스 이미지 생성 실습을 진행하고 GAN/cGAN 학습 결과를 확인하였다. | G6: 75~100% | H6: GAN은 Loss 값만으로 생성 품질을 판단하기 어렵고 실제 생성 이미지를 함께 확인해야 함을 알게 되었다. 또한 조건부 생성에서는 라벨 정보가 Generator가 생성해야 할 이미지 종류를 결정하는 중요한 입력임을 확인하였다. | J6: cGAN의 epoch별 생성 결과를 비교하고 Generator와 Discriminator의 학습 균형 및 결과 이미지 품질을 확인한다.
B7: 26.08.06 | C7: Data Engineer | D7: 원본 이미지와 Annotation JSON 구조를 확인하고 YOLO 학습용 데이터셋으로 변환하기 위한 전처리를 진행하였다. 이미지 파일명, 약품 코드, bbox 정보를 확인하고 이미지와 라벨의 매칭 여부를 검증하였다. | G7: 50~75% | H7: 원본 데이터 용량이 크고 Annotation이 복잡하여 단순 변환보다 이미지-라벨 매칭 검증이 중요함을 확인하였다. 같은 이미지에 포함된 여러 약품 Annotation을 이미지 기준으로 통합해야 하는 구조도 확인하였다. | J7: bbox, 약품 코드, 이미지 파일명의 일치 여부를 검증하고 정상 데이터만 선별하여 YOLO 학습용 데이터셋을 구축한다.
B8: 26.08.07 | C8: Model Architect | D8: 사전학습된 YOLO 기반 Object Detection 모델의 적용 방법을 검토하고, 한 이미지에 존재하는 여러 알약의 위치와 종류를 동시에 예측하는 Direct Multi-class Detection 구조를 설계하였다. | G8: 50~75% | H8: 단순 Classification보다 여러 알약의 위치와 종류를 동시에 탐지해야 하는 프로젝트 목표에는 Object Detection 방식이 적합하다고 판단하였다. 모델 성능뿐 아니라 학습에 사용되는 클래스 범위와 데이터 구성도 중요함을 확인하였다. | J8: YOLO baseline 모델을 학습하고 Precision, Recall, mAP 등의 성능을 평가하여 기본 모델 성능을 확보한다.
B9: 26.08.08 | C9: Experimentation Lead | D9: AI Hub 조합 데이터의 JSON을 분석하여 같은 이미지에 해당하는 Annotation을 file_name 기준으로 통합하고, 약품 코드·bbox·이미지 파일의 정합성을 검사하였다. bbox 시각화 및 Clean Manifest 생성 과정을 통해 학습 가능한 데이터만 선별하였다. | G9: 50~75% | H9: 처음에는 조합 이미지가 모두 4개의 알약으로 구성된 것으로 판단했으나 실제 데이터에는 3~4개 조합이 존재함을 확인하였다. 또한 Annotation 일부가 누락되거나 코드가 일치하지 않는 데이터를 그대로 학습하면 잘못된 라벨로 학습될 수 있음을 확인하였다. | J9: 3~4개 조합을 모두 처리할 수 있도록 정제 조건을 수정하고, Clean dataset을 기반으로 Train/Val/Test 분할 방법을 검토한다.
B10: 26.08.09 | D10: 일요일 | G10: -----
B11: 26.08.10 | C11: Model Architect | D11: AI Hub 공식 Train/Validation 데이터의 클래스 구성을 비교하고, 동일 약품 조합의 유사 촬영 이미지가 서로 다른 split에 포함될 가능성을 분석하였다. 단순 Random Split 대신 약품 조합 단위 Group Split을 적용하는 방법을 검토하고 클래스별 조합 수와 희귀 클래스를 분석하였다. | G11: 75~100% | H11: 공식 Train과 Validation의 약품 클래스가 완전히 일치하지 않아 Train에서 보지 못한 클래스가 평가 데이터에 존재할 수 있음을 확인하였다. 또한 동일 조합을 촬영 각도만 다르게 한 이미지가 Train과 Test에 나뉘면 데이터 누수가 발생할 수 있으며, 일부 희귀 클래스는 조합 수 자체가 적어 모든 split에 포함시키기 어렵다는 점을 발견하였다. | J11: 모든 클래스를 Train에 유지하면서 동일 조합이 split 간 중복되지 않도록 Group Split을 최적화하고, 가능한 범위에서 Validation/Test의 클래스 커버리지를 높인다.
B12: 26.08.11 | C12: Experimentation Lead | D12: AI Hub 조합 데이터 기반 Multi-class YOLO baseline 결과를 정리하고 데이터 범위 확장 방법을 조사하였다. 팀원들과 AI Hub와 Kaggle 데이터의 통합 가능성, 클래스 매핑, 모델 통일 및 공통 평가지표에 대해 논의하였다. 또한 AI Hub 단일 경구약제 5,000종 데이터 활용 가능성을 조사하였다. | G12: 50~75% | H12: 현재 조합 데이터만으로는 실제 식별 가능한 약품 종류가 제한적이며 5,000조합은 5,000개의 약품 클래스가 아니라 조합 수임을 확인하였다. 서로 다른 데이터셋을 합칠 때 JSON 형식 자체는 코드로 변환할 수 있지만 실제 약품 클래스 매핑과 촬영 환경 차이(Domain Shift)가 더 중요한 문제임을 확인하였다. | J12: 팀에서 사용할 데이터 범위와 클래스 체계를 통일하고 YOLO11n/s 등 동일 조건의 모델을 비교한다. 추가로 AI Hub 단일 5,000종 실제 이미지와 JSON을 활용하여 식별 가능한 약품 범위를 확장할 방법을 검토한다.
B13: 26.08.12 | C13: Experimentation Lead | D13: 통일된 이미지·라벨 데이터를 Kaggle 환경에 적용하고, Object Detection 모델 학습을 위한 데이터 경로 및 학습 구조를 구성함. 데이터 로딩부터 모델 학습, 검증, 예측까지 전체 파이프라인이 정상적으로 동작하는지 확인하고 최종 모델 구성을 진행함. | G13: 75~100% | H13: 데이터 형식이 통일되면서 이전보다 학습 파이프라인을 안정적으로 구성할 수 있었음. 다만 모델이 정상적으로 학습되는 것과 실제 제출 성능이 좋은 것은 별개의 문제이므로 validation 결과와 실제 예측 결과를 함께 확인할 필요가 있음. 또한 제출 전 class mapping, bounding box 형식, 파일명 및 submission 형식 오류가 없는지 검증하는 과정이 중요함. | J13: 모델 학습을 최종 완료하고 validation 성능 및 실제 예측 이미지를 확인한 뒤, Kaggle 제출 형식에 맞게 prediction 결과를 변환·검증하여 최종 submission 파일을 생성하고 제출할 예정.
B14: 26.08.13 | C14: 휴가 | D14: 휴가 | G14: -----
B15: 26.08.14 | C15: 휴가 | D15: 휴가 | G15: -----
B16: 26.08.15 | D16: 토요일 | G16: -----
B17: 26.08.16 | D17: 일요일 | G17: -----
B18: 26.08.17 | D18: 공휴일 | G18: -----
B19: 26.08.18 | C19: Sub (지원) | D19: 팀 발표 역할에 맞춰 개인 EDA·모델 분석 내용을 정리하고, 전체 프로젝트의 최종 보고서와 발표 보고서를 나누고 개인 최종보고서를 작성함. | G19: 75~100% | H19: 팀원 모두 기본적인 YOLO 설명은 알고 있으므로 이론 설명보다 실제로 어떤 판단을 했고, 어떤 실험 결과가 나왔으며, 무엇을 발견했는지를 중심으로 발표하는 것이 더 효과적이라고 판단함. | J19: 개인 작업 내용과 발견사항을 팀 발표에서 설명할 수 있도록 정리하고, 모델 결과를 단순 score가 아니라 데이터·검증 구조와 함께 해석
B20: 26.08.19 | C20: Sub (지원) | D20: 최종 프로젝트 결과와 기존 발표자료를 다시 비교하여 내용 밀도를 높이고, EDA → 모델/튜닝 → 구현 로직 → 실험별 score 변화 → 최종 모델 결과가 하나의 흐름으로 이어지도록 PPT·보고서·대본을 작성함 | G20: 25~50% | H20: 평가에서 중요한 것은 최종 score만이 아니라 문제 발견 → 가설 → 처리/실험 → 결과 → 해석의 논리적 연결임. 특히 실패하거나 기대보다 낮았던 결과도 원인 분석과 다음 판단을 보여주면 프로젝트 과정의 중요한 결과가 될 수 있음. | J20: 최종 수치 및 실험 결과 재확인 후 슬라이드별 발표자 내용 확정
B21: 26.08.20 | C21: 휴가 | D21: 공가 | G21: -----
B22: 26.08.21 | G22: -----
B23: 26.08.22 | G23: -----

Sheet 협업일지(고소현)
B1: Project : Fill so Good 개인 협업 일지 (고소현)
B4: 날짜 | C4: 작업 유형 | D4: 구체적인 작업 내용 or 협업내용 | G4: 진행율 | H4: 분석/실험 중 얻은 인사이트나 발견한 문제점 | J4: 목표 or 할일
B5: 26.08.04 | C5: Project Manager | D5: 프로젝트와 관련하여 시간 안배에 관해 제안을 했습니다. 데이터셋과 관련된 최적합 eda를 찾았습니다. | G5: 25~50%
B6: 26.08.05 | C6: Data Engineer | D6: 데이터와 관련하여 eda를 공유하였으며, 어떤 모델 조합이 좋을 지 찾아서 제시했습니다. 어제 찾은 eda에 더 보강할 것들을 찾아 보강했습니다. | G6: 50~75%
B7: 26.08.06 | C7: Project Manager, Model Architect | D7: eda 중에 필요한 부분을 엄선하여 모델을 돌려보았습니다. 그런데 어디에서 잘못된 건지 알약 56개만 실험되었다는 것을 알게 되었습니다. | G7: 75~100%
B8: 26.08.07 | C8: Model Architect | D8: 캐글 모델로 실험을 해서 aihub모델로 돌려보려다가 오류가 계속 났습니다. 그러는 과정에서 다운로드가 너무 많이 시도되어서 24시간 후에 사용할 수 있다는 메시지가 나와서 yolo8 focal loss와 비교할 수 있도록 yolo8+mae, yolo8+swin transformer, yolo8+covNext모델로 작업할 코드를 다시 구현하였습니다. | G8: 25~50%
B9: 26.08.08 | C9: Model Architect, Experimentation Lead | D9: 모델을 실험했고, 하이퍼파라미터 중 로스함수를 바꾸어 성능향상을 경험했습니다. | G9: 75~100%
B10: 26.08.09 | G10: -----
B11: 26.08.10 | C11: Model Architect | D11: yolo11s 모델에 swin, mae, convnext를 붙여서 실험을 했습니다. yolo8모델을 yolo11s모델에 맞춰 다시 코드를 짰습니다. | G11: 75~100%
B12: 26.08.11 | C12: Model Architect | D12: 클래스 불균형을 제거하기 위해 데이터 증강을 했고, 배경색과 질감을 위해 증강을 했습니다. iou 평가지표를 더했습니다. | G12: 25~50%
B13: 26.08.12 | C13: 기타 | G13: -----
B14: 26.08.13 | G14: -----
B15: 26.08.14 | G15: -----
B16: 26.08.15 | G16: -----
B17: 26.08.16 | G17: -----
B18: 26.08.17 | G18: -----
B19: 26.08.18 | G19: -----
B20: 26.08.19 | G20: -----
B21: 26.08.20 | G21: -----
B22: 26.08.21 | G22: -----
B23: 26.08.22 | G23: -----

Sheet 협업일지(서정철)
B1: Project : Fill so Good 개인 협업 일지 (서정철)
B4: 날짜 | C4: 작업 유형 | D4: 구체적인 작업 내용 or 협업내용 | G4: 진행율 | H4: 진행율 근거 | I4: 협업 제안 / 피드백 내용 | J4: 분석/실험 중 얻은 인사이트나 발견한 문제점 | L4: 어려웠던 점 | M4: 목표 or 할일
B5: 26.08.04 | C5: 기타 | D5: 1. 팀 역할 분배 참여 2. Image / Label data 전처리 과정 확인 3. Model 선정 협의 진행 | G5: 50~75% | H5: 1. 역할선정 : Model Architect - 딥러닝 모델을 설계하고 아키텍처를 결정 2. Label data (json) 확인 및 데이터 처리 방향성 공유 3. 경원님과 디스코드 DM으로 Model 선정 협의 진행 | I5: Label data (json)에서 필요한 부분 확인 후 해당 부분이 누락되어있을 경우 해당 데이터 set 별도 처리 진행 방향 제안 | J5: 1. 실제로 json 파일에서 image의 label 부분인 bbox 항목이 없는 json이 있다는 사실을 확인 2. 추가적으로 image folder ↔ label folder간 매칭이 안되는 데이터도 있는 것을 확인 | M5: Model 설계 ↳ 시간이 된다면 모델 training Test 진행
B6: 26.08.05 | C6: Data Engineer | D6: 1. 오전 미팅 회의 결과 각자 End-To-End 방식으로 Model 구현하는 방식으로 선정 2. Data (Image File, json) 파일 분류 진행 2-1) json 파일에 bbox 값 누락, [l,t,w,h] 4개가 완전하지 않을 경우 2-2) 이미지 폴더만 있거나 Label 폴더만 있을 경우 2-3) json 파일 ↔ 이미지 파일 매칭이 안되는 경우 | G6: 50~75% | H6: 1. 분류 중 문제가 되는 data가 계속 나옴... 1) "오류"라는 단어가 들어간 json 파일 존재 2) "copy"라는 단어가 들어간 json 파일 존재 등의 이유로 데이터 분류 작업 시간 걸림 | I6: 멘토링 시간 멘토님께서 말씀해주신 내용으로 각자 초급 프로젝트를 한번씩 해보는 방향에 공감 | J6: 1. dataset issue 1) json 파일에 bbox 값 누락, [l,t,w,h] 4개가 완전하지 않을 경우 2) 이미지 폴더만 있거나 Label 폴더만 있을 경우 3) json 파일 ↔ 이미지 파일 매칭이 안되는 경우 4) "오류"라는 단어가 들어간 json 파일 존재 5) "copy"라는 단어가 들어간 json 파일 존재 등 여러가지 data 파일에 문제가 있음 | L6: 1. Visual Studio Code를 진행하면서 Python 환경이 안맞아서 Debug 환경과 terminal에서 작성하는 python .py 파일을 했을 때 Python 버전 및 import, install 한 라이브러리가 달라 실행이 안되는 현상 발생 -> .vscode폴더 생성, 그 안에 setting.json과 launch.json생성, 폴더째 vscode에서 load | M6: 1. 데이터 분류 완료 2. 뼈대 구축 3. 시간이 된다면 training 진행
B7: 26.08.06 | C7: Model Architect, Data Engineer | D7: 1. image, png 파일 정상 data 분류 2. Faster RCNN Model 뼈대 제작 3. Training 진행중 | G7: 25~50% | H7: 1. json 확인 시 bbox 값 오류가 있는 data 추가 분류 진행 2. Faster RCNN model 학습 진행 중 | J7: 1. json 파일이 휴먼에러가 발생한 경우가 다수있는것으로 파악됨, 해당 파일 제외 필요 | L7: 1. 아직 제대로 학습을 진행하지 않았는데 예측한 bbox가 1개의 object에서 2개로 나오는 경우를 확인 -> 학습 후 확인 필요 | M7: training -> test set 까지 점수 확인
B8: 26.08.07 | C8: Model Architect, Data Engineer | D8: 1. 팀원 전체가 각각 end-to-end 방식으로 진행한 내용에 대해 미팅 진행 2. 차주 월까지 구현 및 발표 예정 | G8: 50~75% | H8: 1. 1차적으로 FasterRCNN Model 검증 완료 | J8: 1. AI-HUB Data set 전체에 bounding box error가 다수 있음, 직접 draw하여 해당 data 제외하는 선별하는 작업이 필요함 | L8: 1. testset 확인 시 GT Rect가 틀어지는 경우가 확인됨 -> train dataset에서도 실제 rect가 다 맞는지 확인 필요함 2. train dataset bounding box 확인 시 이미지 저장 할 때 메모리 누적 증가 -> draw 부분 (plt, data 등) 함수 마지막에 초기화 -> vscode 재시작 후 필요한 부분 실행했더니 메모리 증가 안함 (ipynb로 작업 중 - 실행 시 전체 실행함에 번거로움이 있어 ipynb로 작업) 3. training 1epoch 당 30분 걸림, gpu 확인 필요 | M8: 1. Dataset bounding box 확인 후 data 제외 작업 2. training epoch 증가 및 training 속도 확인 (gpu 사용 확인) 3. 시간이 된다면 다른 Model Test
B9: 26.08.08
B10: 26.08.09 | G10: -----
B11: 26.08.10 | C11: Model Architect | D11: 1. 팀원 전체가 공통된 Data를 사용하기로 함 -> AI-hub data에서 Kaggle data 2. 팀원 각자 kaggle에 한번씩 업로드하여 점수를 보기로 함 | G11: 25~50% | H11: 1. kaggle dataset 분석하여 dataset에 맞게 소스 수정 | I11: 1. AI-Hub dataset을 가공하여 사용하는 것을 제안, training + validation data를 합친 이유로 데이터 누수 고민 | J11: 1. kaggle dataset 또한 error가 많음 | L11: 1. training data + validation data를 합친 후 비율에 맞게 split을 하면 데이터 누수가 발생하는지 궁금함 | M11: 1. kaggle data에 맞게 faster r-cnn 결과 확인
B12: 26.08.11 | C12: Model Architect | D12: 1. 강사님과 데일리 스크럼 진행 1) dataset 사용방법 (kaggle + 추가적으로 필요한 data를 aihub data를 통해 json 파일 수정하여 사용 가능) 2) 추천하는 평가 지표 : IoU, mAP 2.Kaggle dataset을 이용하여 Faster RCNN Model을 진행 3. test 결과를 확인하였는데 실제 gt rect와 예측 rect의 label이 다름 확인, 검출하지 못한 객체도 발생 | G12: 25~50% | H12: 1. Faster RCNN 평가 지표 결과 공유 | J12: 1. kaggle dataset 과 ai-hub dataset의 class를 확인하였는데 kaggle에만 존재하는 2가지 class가 존재함 | L12: 1. kaggle dataset을 이용한 faster RCNN Model의 성능이 좋게 나오지 않아 data 추가 필요 | M12: 1. ai-hub dataset과 kaggle dataset을 merge하여 training 예정
B13: 26.08.12 | C13: Model Architect | D13: 1. kaggle + aihub dataset 이용하여 kaggle upload 후 score 확인 2. score 확인 : 약 0.58 확인 후 test image에 rect draw하여 이미지 확인 3. score가 낮은 경우 발생 -> 1개의 알약에 대해 여러개의 오탐 -> 1개의 알약 탐지 + 다른 위치 같은 label 탐지 | G13: 25~50% | H13: kaggle에 test data를 이용하여 score 확인함 | J13: 1. test set의 result 확인 시 -> 1개의 알약에 대해 여러개의 오탐 -> 1개의 알약 탐지 + 다른 위치 같은 label 탐지 ->오탐일 경우 score가 낮아 threshold로 방지를 해야할지 추가 방안이 있을지 확인 필요 | M13: IoU 확인 예정
B14: 26.08.13 | C14: Data Engineer | D14: 1. model이 testset에서 예측한 label과 실제 label (알약 확인) 비교 진행 2. test set에서 k-005000과 같은 오탐이 있는지 확인 진행 중 | G14: 25~50% | I14: kaggle에 제출한 팀원들의 csv 확인하여 문제가 됐던 이미지의 오탐 확인, 팀원들에게 전달 | J14: 실제로 model이 test set을 이용하여 검출한 결과 실제 약 label과 다르게 detect한 것을 확인함 | L14: 알약 오탐을 확인 - 파일 탐색기에서 썸네일로 색상 등 으로 확인 (알약 글씨 등 중요할 경우 클릭해서 확대) | M14: 추가 오탐 여부 확인 및 부족한 class의 data 보충하여 학습
B15: 26.08.14 | C15: 휴가 | G15: -----
B16: 26.08.15 | G16: -----
B17: 26.08.16 | G17: -----
B18: 26.08.17 | G18: -----
B19: 26.08.18 | C19: Sub (지원) | D19: 1. YOLO8m 모델 Training 진행 (100 Epoch) 2. 발표 자료 제작 서브 담당 업무 진행 (with 혜원님) | G19: 0~25% | J19: 팀원 전체가 발표 진행 필요 | L19: 전체 팀원의 발표 내용을 Kaggle에서 최고 점수를 받은 경원님의 모델을 가지고 작성해야함으로 경원님의 소스, 데이터를 분석 후 발표자료를 만들어야함 | M19: 혜원님과 발표 자료 만들기
B20: 26.08.19 | C20: Sub (지원) | D20: 1. 발표 자료 및 발표 대본 제작 서브 진행 | G20: 50~75% | H20: 발표 자료를 토대로 팀원 미팅 진행 | M20: 발표 자료 수정 및 발표 대본 만들기
B21: 26.08.20 | G21: -----
B22: 26.08.21 | G22: -----
B23: 26.08.22 | G23: -----

Sheet 협력일지(김경원)
B1: Project : Fill so Good 개인 협업 일지 (김경원)
B4: 날짜 | C4: 작업 유형 | D4: 구체적인 작업 내용 or 협업내용 | G4: 진행율 | H4: 분석/실험 중 얻은 인사이트나 발견한 문제점 | J4: 목표 or 할일
B5: 26.08.04 | C5: 개인 Project | D5: - 팀 역할 분배 - 너무 많은 기능적 희망사항을 제한하고, 수집할 수 있는 데이터 내에서 만들어낼 수 있는 기능을 생각해볼 것을 제안 - 래퍼런스 탐색 및 공유 -4개의 알약 사진을 한개씩 잘라서 학습시킬것이냐, 4개의 알약을 한번에 할습 시킬것이냐는 의견충돌이 있었음 → 가설을 검증하고, 좋은 성능 또는 효율을 나타내는 것을 채택하는 것을 제안함. | G5: 25~50%
B6: 26.08.05 | C6: 개인 Project | D6: 모두가 각자 a to z로 모델을 만들어보기로 한 상황, 각자 다른 모델을 담당해서 더 나은 모델을 찾아보자는 의견이 있었음. 그럼, 모델을 제외한 다른 모든 변수를 통제해야하는데, 각자 a to z를 하는 상황에서 현실적으로 불가능 하다는 의견을 냄 이에 따라서, 각자 여러 모델을 돌려보기로 함 | G6: -----
B7: 26.08.06 | C7: 개인 Project | D7: - EDA, 데이터 분할, 데이터 증강, 평가지표, 모델 선정(Faster R-CNN, RetinaNet, FCOS, YOLO11s) | G7: ----- | H7: annotaion 오타 발견, 사진 좌우상하 반전은 거울상이 되어서 회전만 할 수있다.
B8: 26.08.07 | C8: 개인 Project | D8: - 팀원 전체가 a to z 만들어서 월요일 발표 합의 - 모델 설계 및 학습 | G8: ----- | H8: - 평가지표 mAP 뿐만 아니라, F1, F2 스코어가 실제 상황에서 더 적합함을 알게됨
B9: 26.08.08 | G9: -----
B10: 26.08.09 | G10: -----
B11: 26.08.10 | C11: 개인 Project | D11: - 각각의 모델 설계 과정 및 결과 공유 - 캐글에 올리고, 점수 확인해보기로 합의 - 캐글에 올리기 위한 처리작업 | G11: -----
B12: 26.08.11 | C12: 휴가 | G12: -----
B13: 26.08.12 | C13: 개인 Project | D13: - 56종 알약 원본 데이터 확보 - 데이터 확보 후 캐글 제출 | G13: ----- | H13: - 가중표집, 사전확률 보정 개념에 대해서 알게됨 - 데이터가 적을때와 많을때 점수차이가 크지 않음 - 알약 찾기 자체는 잘함, 어떤 알약인지에서 틀리는 경우가 많음
B14: 26.08.13 | C14: 개인 Project | D14: - 더 많은 데이터(희귀 클래스) 확보 후, 캐글 제출 - | G14: ----- | H14: - 캐글 제공 데이터 이외의 클래스가 test에 포함되어있음 - 여러 클래스 확보 후 점수 크게 향상됨
B15: 26.08.14 | C15: 개인 Project | D15: - 2 stage 방식에서 크롭의 해상도를 높이는 시도를 함 -> 자체 test에서는 적은 에폭에도 좋은 점수가 나와서, 얼리스토핑 없애고 100에폭 고정, 손실곡선으로 수렴 판단 - 여태까지는 분류기에만 더 많은 학습 데이터를 줬었는데, 검출기에도 더 많은 학습데이터를 주니 점수가 소폭 상승함 | G15: ----- | H15: - 자체 test로는 점수가 매우 높게나와 의미가 없다고 판단함.그래서 얼리스토핑을 없애고, 손실곡선으로 수렴을 판단. - 추가로, 여러 에폭의 자료들을 제출하면서 실제 캐글에서 어떤 에폭이 점수가 높은지 확인함
B16: 26.08.15 | G16: -----
B17: 26.08.16 | G17: -----
B18: 26.08.17 | C18: 개인 Project | D18: - 크롭된 사진의 해상도 높이기 + 증강 강화시도로 점수 소폭 상승 | G18: -----
B19: 26.08.18 | C19: 개인 Project | D19: - 같은모델이지만, 데이터, 크롭, 에폭이 다른 것들을 앙상블 시도로 점수 소폭 상승 - 앙상블 6개 점수상승, 9개 점수 상승, 10개이상부터 점수 하락 | G19: ----- | H19: 앙상블이 많아진다고 좋은 결과로 이어지는것은 아님.
B20: 26.08.19 | C20: 개인 Project | D20: - 검출기 데이터 확장 재학습 - 캐글 test data를 학습데이터로 끌어오는 의사라벨 분류기를 앙상블에 추가함 | G20: ----- | H20: - 헛검출이 점수를 막는 요인이었다.
B21: 26.08.20 | G21: -----
B22: 26.08.21 | G22: -----
B23: 26.08.22 | G23: -----

Sheet 협력일지(나상훈)
B1: Project : Fill so Good 개인 협업 일지 (나상훈)
B4: 날짜 | C4: 작업 유형 | D4: 구체적인 작업 내용 or 협업내용 | G4: 진행율 | H4: 분석/실험 중 얻은 인사이트나 발견한 문제점 | J4: 목표 or 할일
